[2025-04-23T03:01:26.202+0000] {local_task_job_runner.py:123} INFO - ::group::Pre task execution logs
[2025-04-23T03:01:26.227+0000] {taskinstance.py:2612} INFO - Dependencies all met for dep_context=non-requeueable deps ti=<TaskInstance: BuildELT_dbt.dbt_run manual__2025-04-23T03:01:25.278548+00:00 [queued]>
[2025-04-23T03:01:26.247+0000] {taskinstance.py:2612} INFO - Dependencies all met for dep_context=requeueable deps ti=<TaskInstance: BuildELT_dbt.dbt_run manual__2025-04-23T03:01:25.278548+00:00 [queued]>
[2025-04-23T03:01:26.248+0000] {taskinstance.py:2865} INFO - Starting attempt 1 of 1
[2025-04-23T03:01:26.276+0000] {taskinstance.py:2888} INFO - Executing <Task(BashOperator): dbt_run> on 2025-04-23 03:01:25.278548+00:00
[2025-04-23T03:01:26.288+0000] {standard_task_runner.py:104} INFO - Running: ['***', 'tasks', 'run', 'BuildELT_dbt', 'dbt_run', 'manual__2025-04-23T03:01:25.278548+00:00', '--job-id', '52', '--raw', '--subdir', 'DAGS_FOLDER/build_elt_with_dbt.py', '--cfg-path', '/tmp/tmp8vuwrl83']
[2025-04-23T03:01:26.292+0000] {standard_task_runner.py:105} INFO - Job 52: Subtask dbt_run
[2025-04-23T03:01:26.292+0000] {logging_mixin.py:190} WARNING - /home/***/.local/lib/python3.12/site-packages/***/task/task_runner/standard_task_runner.py:70 DeprecationWarning: This process (pid=761) is multi-threaded, use of fork() may lead to deadlocks in the child.
[2025-04-23T03:01:26.293+0000] {standard_task_runner.py:72} INFO - Started process 762 to run task
[2025-04-23T03:01:26.373+0000] {task_command.py:467} INFO - Running <TaskInstance: BuildELT_dbt.dbt_run manual__2025-04-23T03:01:25.278548+00:00 [running]> on host dbfa88ee86fe
[2025-04-23T03:01:26.557+0000] {taskinstance.py:3131} INFO - Exporting env vars: AIRFLOW_CTX_DAG_OWNER='***' AIRFLOW_CTX_DAG_ID='BuildELT_dbt' AIRFLOW_CTX_TASK_ID='dbt_run' AIRFLOW_CTX_EXECUTION_DATE='2025-04-23T03:01:25.278548+00:00' AIRFLOW_CTX_TRY_NUMBER='1' AIRFLOW_CTX_DAG_RUN_ID='manual__2025-04-23T03:01:25.278548+00:00'
[2025-04-23T03:01:26.560+0000] {taskinstance.py:731} INFO - ::endgroup::
[2025-04-23T03:01:26.620+0000] {subprocess.py:63} INFO - Tmp dir root location: /tmp
[2025-04-23T03:01:26.628+0000] {subprocess.py:75} INFO - Running command: ['/usr/bin/bash', '-c', '/home/***/.local/bin/dbt run --profiles-dir /opt/***/dbt --project-dir /opt/***/dbt']
[2025-04-23T03:01:26.644+0000] {subprocess.py:86} INFO - Output:
[2025-04-23T03:01:30.741+0000] {subprocess.py:93} INFO - [0m03:01:30  Running with dbt=1.6.18
[2025-04-23T03:01:32.141+0000] {subprocess.py:93} INFO - [0m03:01:32  Registered adapter: snowflake=1.6.0
[2025-04-23T03:01:32.450+0000] {subprocess.py:93} INFO - [0m03:01:32  Found 3 models, 2 tests, 2 sources, 0 exposures, 0 metrics, 375 macros, 0 groups, 0 semantic models
[2025-04-23T03:01:32.454+0000] {subprocess.py:93} INFO - [0m03:01:32
[2025-04-23T03:01:34.983+0000] {subprocess.py:93} INFO - [0m03:01:34  Concurrency: 1 threads (target='dev')
[2025-04-23T03:01:34.984+0000] {subprocess.py:93} INFO - [0m03:01:34
[2025-04-23T03:01:34.998+0000] {subprocess.py:93} INFO - [0m03:01:34  1 of 2 START sql view model analytics.law_enforcement_calls .................... [RUN]
[2025-04-23T03:01:36.082+0000] {subprocess.py:93} INFO - [0m03:01:36  1 of 2 ERROR creating sql view model analytics.law_enforcement_calls ........... [[31mERROR[0m in 1.08s]
[2025-04-23T03:01:36.090+0000] {subprocess.py:93} INFO - [0m03:01:36  2 of 2 SKIP relation analytics.Avg_response_time_pd ............................ [[33mSKIP[0m]
[2025-04-23T03:01:36.101+0000] {subprocess.py:93} INFO - [0m03:01:36
[2025-04-23T03:01:36.102+0000] {subprocess.py:93} INFO - [0m03:01:36  Finished running 2 view models in 0 hours 0 minutes and 3.64 seconds (3.64s).
[2025-04-23T03:01:36.156+0000] {subprocess.py:93} INFO - [0m03:01:36
[2025-04-23T03:01:36.157+0000] {subprocess.py:93} INFO - [0m03:01:36  [31mCompleted with 1 error and 0 warnings:[0m
[2025-04-23T03:01:36.159+0000] {subprocess.py:93} INFO - [0m03:01:36
[2025-04-23T03:01:36.160+0000] {subprocess.py:93} INFO - [0m03:01:36    Database Error in model law_enforcement_calls (models/input/law_enforcement_calls.sql)
[2025-04-23T03:01:36.161+0000] {subprocess.py:93} INFO -   000904 (42000): SQL compilation error: error line 11 at position 8
[2025-04-23T03:01:36.162+0000] {subprocess.py:93} INFO -   invalid identifier 'DISPATCH_TO_RECEIVED'
[2025-04-23T03:01:36.162+0000] {subprocess.py:93} INFO -   compiled Code at target/run/lab2_dbt/models/input/law_enforcement_calls.sql
[2025-04-23T03:01:36.163+0000] {subprocess.py:93} INFO - [0m03:01:36
[2025-04-23T03:01:36.164+0000] {subprocess.py:93} INFO - [0m03:01:36  Done. PASS=0 WARN=0 ERROR=1 SKIP=1 TOTAL=2
[2025-04-23T03:01:38.133+0000] {subprocess.py:97} INFO - Command exited with return code 1
[2025-04-23T03:01:38.179+0000] {taskinstance.py:3310} ERROR - Task failed with exception
Traceback (most recent call last):
  File "/home/airflow/.local/lib/python3.12/site-packages/airflow/models/taskinstance.py", line 767, in _execute_task
    result = _execute_callable(context=context, **execute_callable_kwargs)
             ^^^^^^^^^^^^^^^^^^^^^^^^^^^^^^^^^^^^^^^^^^^^^^^^^^^^^^^^^^^^^
  File "/home/airflow/.local/lib/python3.12/site-packages/airflow/models/taskinstance.py", line 733, in _execute_callable
    return ExecutionCallableRunner(
           ^^^^^^^^^^^^^^^^^^^^^^^^
  File "/home/airflow/.local/lib/python3.12/site-packages/airflow/utils/operator_helpers.py", line 252, in run
    return self.func(*args, **kwargs)
           ^^^^^^^^^^^^^^^^^^^^^^^^^^
  File "/home/airflow/.local/lib/python3.12/site-packages/airflow/models/baseoperator.py", line 406, in wrapper
    return func(self, *args, **kwargs)
           ^^^^^^^^^^^^^^^^^^^^^^^^^^^
  File "/home/airflow/.local/lib/python3.12/site-packages/airflow/operators/bash.py", line 249, in execute
    raise AirflowException(
airflow.exceptions.AirflowException: Bash command failed. The command returned a non-zero exit code 1.
[2025-04-23T03:01:38.202+0000] {taskinstance.py:1225} INFO - Marking task as FAILED. dag_id=BuildELT_dbt, task_id=dbt_run, run_id=manual__2025-04-23T03:01:25.278548+00:00, execution_date=20250423T030125, start_date=20250423T030126, end_date=20250423T030138
[2025-04-23T03:01:38.238+0000] {taskinstance.py:340} INFO - ::group::Post task execution logs
[2025-04-23T03:01:38.239+0000] {standard_task_runner.py:124} ERROR - Failed to execute job 52 for task dbt_run (Bash command failed. The command returned a non-zero exit code 1.; 762)
Traceback (most recent call last):
  File "/home/airflow/.local/lib/python3.12/site-packages/airflow/task/task_runner/standard_task_runner.py", line 117, in _start_by_fork
    ret = args.func(args, dag=self.dag)
          ^^^^^^^^^^^^^^^^^^^^^^^^^^^^^
  File "/home/airflow/.local/lib/python3.12/site-packages/airflow/cli/cli_config.py", line 49, in command
    return func(*args, **kwargs)
           ^^^^^^^^^^^^^^^^^^^^^
  File "/home/airflow/.local/lib/python3.12/site-packages/airflow/utils/cli.py", line 115, in wrapper
    return f(*args, **kwargs)
           ^^^^^^^^^^^^^^^^^^
  File "/home/airflow/.local/lib/python3.12/site-packages/airflow/cli/commands/task_command.py", line 483, in task_run
    task_return_code = _run_task_by_selected_method(args, _dag, ti)
                       ^^^^^^^^^^^^^^^^^^^^^^^^^^^^^^^^^^^^^^^^^^^^
  File "/home/airflow/.local/lib/python3.12/site-packages/airflow/cli/commands/task_command.py", line 256, in _run_task_by_selected_method
    return _run_raw_task(args, ti)
           ^^^^^^^^^^^^^^^^^^^^^^^
  File "/home/airflow/.local/lib/python3.12/site-packages/airflow/cli/commands/task_command.py", line 341, in _run_raw_task
    return ti._run_raw_task(
           ^^^^^^^^^^^^^^^^^
  File "/home/airflow/.local/lib/python3.12/site-packages/airflow/utils/session.py", line 97, in wrapper
    return func(*args, session=session, **kwargs)
           ^^^^^^^^^^^^^^^^^^^^^^^^^^^^^^^^^^^^^^
  File "/home/airflow/.local/lib/python3.12/site-packages/airflow/models/taskinstance.py", line 3004, in _run_raw_task
    return _run_raw_task(
           ^^^^^^^^^^^^^^
  File "/home/airflow/.local/lib/python3.12/site-packages/airflow/models/taskinstance.py", line 273, in _run_raw_task
    TaskInstance._execute_task_with_callbacks(
  File "/home/airflow/.local/lib/python3.12/site-packages/airflow/models/taskinstance.py", line 3158, in _execute_task_with_callbacks
    result = self._execute_task(context, task_orig)
             ^^^^^^^^^^^^^^^^^^^^^^^^^^^^^^^^^^^^^^
  File "/home/airflow/.local/lib/python3.12/site-packages/airflow/models/taskinstance.py", line 3182, in _execute_task
    return _execute_task(self, context, task_orig)
           ^^^^^^^^^^^^^^^^^^^^^^^^^^^^^^^^^^^^^^^
  File "/home/airflow/.local/lib/python3.12/site-packages/airflow/models/taskinstance.py", line 767, in _execute_task
    result = _execute_callable(context=context, **execute_callable_kwargs)
             ^^^^^^^^^^^^^^^^^^^^^^^^^^^^^^^^^^^^^^^^^^^^^^^^^^^^^^^^^^^^^
  File "/home/airflow/.local/lib/python3.12/site-packages/airflow/models/taskinstance.py", line 733, in _execute_callable
    return ExecutionCallableRunner(
           ^^^^^^^^^^^^^^^^^^^^^^^^
  File "/home/airflow/.local/lib/python3.12/site-packages/airflow/utils/operator_helpers.py", line 252, in run
    return self.func(*args, **kwargs)
           ^^^^^^^^^^^^^^^^^^^^^^^^^^
  File "/home/airflow/.local/lib/python3.12/site-packages/airflow/models/baseoperator.py", line 406, in wrapper
    return func(self, *args, **kwargs)
           ^^^^^^^^^^^^^^^^^^^^^^^^^^^
  File "/home/airflow/.local/lib/python3.12/site-packages/airflow/operators/bash.py", line 249, in execute
    raise AirflowException(
airflow.exceptions.AirflowException: Bash command failed. The command returned a non-zero exit code 1.
[2025-04-23T03:01:38.288+0000] {local_task_job_runner.py:266} INFO - Task exited with return code 1
[2025-04-23T03:01:38.333+0000] {taskinstance.py:3900} INFO - 0 downstream tasks scheduled from follow-on schedule check
[2025-04-23T03:01:38.343+0000] {local_task_job_runner.py:245} INFO - ::endgroup::
