[2025-04-22T06:13:25.447+0000] {local_task_job_runner.py:123} INFO - ::group::Pre task execution logs
[2025-04-22T06:13:25.476+0000] {taskinstance.py:2612} INFO - Dependencies all met for dep_context=non-requeueable deps ti=<TaskInstance: BuildELT_dbt.dbt_run manual__2025-04-22T06:13:24.459692+00:00 [queued]>
[2025-04-22T06:13:25.493+0000] {taskinstance.py:2612} INFO - Dependencies all met for dep_context=requeueable deps ti=<TaskInstance: BuildELT_dbt.dbt_run manual__2025-04-22T06:13:24.459692+00:00 [queued]>
[2025-04-22T06:13:25.494+0000] {taskinstance.py:2865} INFO - Starting attempt 1 of 1
[2025-04-22T06:13:25.513+0000] {taskinstance.py:2888} INFO - Executing <Task(BashOperator): dbt_run> on 2025-04-22 06:13:24.459692+00:00
[2025-04-22T06:13:25.523+0000] {standard_task_runner.py:104} INFO - Running: ['***', 'tasks', 'run', 'BuildELT_dbt', 'dbt_run', 'manual__2025-04-22T06:13:24.459692+00:00', '--job-id', '46', '--raw', '--subdir', 'DAGS_FOLDER/build_elt_with_dbt.py', '--cfg-path', '/tmp/tmp2c1j7cie']
[2025-04-22T06:13:25.527+0000] {standard_task_runner.py:105} INFO - Job 46: Subtask dbt_run
[2025-04-22T06:13:25.529+0000] {logging_mixin.py:190} WARNING - /home/***/.local/lib/python3.12/site-packages/***/task/task_runner/standard_task_runner.py:70 DeprecationWarning: This process (pid=433) is multi-threaded, use of fork() may lead to deadlocks in the child.
[2025-04-22T06:13:25.531+0000] {standard_task_runner.py:72} INFO - Started process 434 to run task
[2025-04-22T06:13:25.589+0000] {task_command.py:467} INFO - Running <TaskInstance: BuildELT_dbt.dbt_run manual__2025-04-22T06:13:24.459692+00:00 [running]> on host d596f66563f7
[2025-04-22T06:13:25.700+0000] {taskinstance.py:3131} INFO - Exporting env vars: AIRFLOW_CTX_DAG_OWNER='***' AIRFLOW_CTX_DAG_ID='BuildELT_dbt' AIRFLOW_CTX_TASK_ID='dbt_run' AIRFLOW_CTX_EXECUTION_DATE='2025-04-22T06:13:24.459692+00:00' AIRFLOW_CTX_TRY_NUMBER='1' AIRFLOW_CTX_DAG_RUN_ID='manual__2025-04-22T06:13:24.459692+00:00'
[2025-04-22T06:13:25.701+0000] {taskinstance.py:731} INFO - ::endgroup::
[2025-04-22T06:13:25.729+0000] {subprocess.py:63} INFO - Tmp dir root location: /tmp
[2025-04-22T06:13:25.732+0000] {subprocess.py:75} INFO - Running command: ['/usr/bin/bash', '-c', '/home/***/.local/bin/dbt run --profiles-dir /opt/***/dbt --project-dir /opt/***/dbt']
[2025-04-22T06:13:25.742+0000] {subprocess.py:86} INFO - Output:
[2025-04-22T06:13:29.303+0000] {subprocess.py:93} INFO - [0m06:13:29  Running with dbt=1.6.18
[2025-04-22T06:13:30.614+0000] {subprocess.py:93} INFO - [0m06:13:30  Registered adapter: snowflake=1.6.0
[2025-04-22T06:13:30.660+0000] {subprocess.py:93} INFO - [0m06:13:30  Unable to do partial parsing because of a version mismatch
[2025-04-22T06:13:31.675+0000] {subprocess.py:93} INFO - [0m06:13:31  [[33mWARNING[0m]: Did not find matching node for patch with name 'final_district_performance' in the 'models' section of file 'models/output/schema.yml'
[2025-04-22T06:13:31.705+0000] {subprocess.py:93} INFO - [0m06:13:31  [[33mWARNING[0m]: Test 'test.lab2_dbt.not_null_final_district_performance_police_district.903b2f46c9' (models/output/schema.yml) depends on a node named 'final_district_performance' in package '' which was not found
[2025-04-22T06:13:31.783+0000] {subprocess.py:93} INFO - [0m06:13:31  Found 3 models, 2 tests, 2 sources, 0 exposures, 0 metrics, 375 macros, 0 groups, 0 semantic models
[2025-04-22T06:13:31.786+0000] {subprocess.py:93} INFO - [0m06:13:31
[2025-04-22T06:13:31.817+0000] {subprocess.py:93} INFO - [0m06:13:31
[2025-04-22T06:13:31.818+0000] {subprocess.py:93} INFO - [0m06:13:31  Finished running  in 0 hours 0 minutes and 0.03 seconds (0.03s).
[2025-04-22T06:13:31.819+0000] {subprocess.py:93} INFO - [0m06:13:31  Encountered an error:
[2025-04-22T06:13:31.820+0000] {subprocess.py:93} INFO - Runtime Error
[2025-04-22T06:13:31.820+0000] {subprocess.py:93} INFO -   Database error while listing schemas in database "dev"
[2025-04-22T06:13:31.820+0000] {subprocess.py:93} INFO -   Database Error
[2025-04-22T06:13:31.821+0000] {subprocess.py:93} INFO -     251005: User is empty
[2025-04-22T06:13:32.914+0000] {subprocess.py:97} INFO - Command exited with return code 2
[2025-04-22T06:13:32.931+0000] {taskinstance.py:3310} ERROR - Task failed with exception
Traceback (most recent call last):
  File "/home/airflow/.local/lib/python3.12/site-packages/airflow/models/taskinstance.py", line 767, in _execute_task
    result = _execute_callable(context=context, **execute_callable_kwargs)
             ^^^^^^^^^^^^^^^^^^^^^^^^^^^^^^^^^^^^^^^^^^^^^^^^^^^^^^^^^^^^^
  File "/home/airflow/.local/lib/python3.12/site-packages/airflow/models/taskinstance.py", line 733, in _execute_callable
    return ExecutionCallableRunner(
           ^^^^^^^^^^^^^^^^^^^^^^^^
  File "/home/airflow/.local/lib/python3.12/site-packages/airflow/utils/operator_helpers.py", line 252, in run
    return self.func(*args, **kwargs)
           ^^^^^^^^^^^^^^^^^^^^^^^^^^
  File "/home/airflow/.local/lib/python3.12/site-packages/airflow/models/baseoperator.py", line 406, in wrapper
    return func(self, *args, **kwargs)
           ^^^^^^^^^^^^^^^^^^^^^^^^^^^
  File "/home/airflow/.local/lib/python3.12/site-packages/airflow/operators/bash.py", line 249, in execute
    raise AirflowException(
airflow.exceptions.AirflowException: Bash command failed. The command returned a non-zero exit code 2.
[2025-04-22T06:13:32.940+0000] {taskinstance.py:1225} INFO - Marking task as FAILED. dag_id=BuildELT_dbt, task_id=dbt_run, run_id=manual__2025-04-22T06:13:24.459692+00:00, execution_date=20250422T061324, start_date=20250422T061325, end_date=20250422T061332
[2025-04-22T06:13:32.961+0000] {taskinstance.py:340} INFO - ::group::Post task execution logs
[2025-04-22T06:13:32.962+0000] {standard_task_runner.py:124} ERROR - Failed to execute job 46 for task dbt_run (Bash command failed. The command returned a non-zero exit code 2.; 434)
Traceback (most recent call last):
  File "/home/airflow/.local/lib/python3.12/site-packages/airflow/task/task_runner/standard_task_runner.py", line 117, in _start_by_fork
    ret = args.func(args, dag=self.dag)
          ^^^^^^^^^^^^^^^^^^^^^^^^^^^^^
  File "/home/airflow/.local/lib/python3.12/site-packages/airflow/cli/cli_config.py", line 49, in command
    return func(*args, **kwargs)
           ^^^^^^^^^^^^^^^^^^^^^
  File "/home/airflow/.local/lib/python3.12/site-packages/airflow/utils/cli.py", line 115, in wrapper
    return f(*args, **kwargs)
           ^^^^^^^^^^^^^^^^^^
  File "/home/airflow/.local/lib/python3.12/site-packages/airflow/cli/commands/task_command.py", line 483, in task_run
    task_return_code = _run_task_by_selected_method(args, _dag, ti)
                       ^^^^^^^^^^^^^^^^^^^^^^^^^^^^^^^^^^^^^^^^^^^^
  File "/home/airflow/.local/lib/python3.12/site-packages/airflow/cli/commands/task_command.py", line 256, in _run_task_by_selected_method
    return _run_raw_task(args, ti)
           ^^^^^^^^^^^^^^^^^^^^^^^
  File "/home/airflow/.local/lib/python3.12/site-packages/airflow/cli/commands/task_command.py", line 341, in _run_raw_task
    return ti._run_raw_task(
           ^^^^^^^^^^^^^^^^^
  File "/home/airflow/.local/lib/python3.12/site-packages/airflow/utils/session.py", line 97, in wrapper
    return func(*args, session=session, **kwargs)
           ^^^^^^^^^^^^^^^^^^^^^^^^^^^^^^^^^^^^^^
  File "/home/airflow/.local/lib/python3.12/site-packages/airflow/models/taskinstance.py", line 3004, in _run_raw_task
    return _run_raw_task(
           ^^^^^^^^^^^^^^
  File "/home/airflow/.local/lib/python3.12/site-packages/airflow/models/taskinstance.py", line 273, in _run_raw_task
    TaskInstance._execute_task_with_callbacks(
  File "/home/airflow/.local/lib/python3.12/site-packages/airflow/models/taskinstance.py", line 3158, in _execute_task_with_callbacks
    result = self._execute_task(context, task_orig)
             ^^^^^^^^^^^^^^^^^^^^^^^^^^^^^^^^^^^^^^
  File "/home/airflow/.local/lib/python3.12/site-packages/airflow/models/taskinstance.py", line 3182, in _execute_task
    return _execute_task(self, context, task_orig)
           ^^^^^^^^^^^^^^^^^^^^^^^^^^^^^^^^^^^^^^^
  File "/home/airflow/.local/lib/python3.12/site-packages/airflow/models/taskinstance.py", line 767, in _execute_task
    result = _execute_callable(context=context, **execute_callable_kwargs)
             ^^^^^^^^^^^^^^^^^^^^^^^^^^^^^^^^^^^^^^^^^^^^^^^^^^^^^^^^^^^^^
  File "/home/airflow/.local/lib/python3.12/site-packages/airflow/models/taskinstance.py", line 733, in _execute_callable
    return ExecutionCallableRunner(
           ^^^^^^^^^^^^^^^^^^^^^^^^
  File "/home/airflow/.local/lib/python3.12/site-packages/airflow/utils/operator_helpers.py", line 252, in run
    return self.func(*args, **kwargs)
           ^^^^^^^^^^^^^^^^^^^^^^^^^^
  File "/home/airflow/.local/lib/python3.12/site-packages/airflow/models/baseoperator.py", line 406, in wrapper
    return func(self, *args, **kwargs)
           ^^^^^^^^^^^^^^^^^^^^^^^^^^^
  File "/home/airflow/.local/lib/python3.12/site-packages/airflow/operators/bash.py", line 249, in execute
    raise AirflowException(
airflow.exceptions.AirflowException: Bash command failed. The command returned a non-zero exit code 2.
[2025-04-22T06:13:32.992+0000] {local_task_job_runner.py:266} INFO - Task exited with return code 1
[2025-04-22T06:13:33.023+0000] {taskinstance.py:3900} INFO - 0 downstream tasks scheduled from follow-on schedule check
[2025-04-22T06:13:33.028+0000] {local_task_job_runner.py:245} INFO - ::endgroup::
