[2025-04-20T21:44:16.049+0000] {processor.py:186} INFO - Started process (PID=372) to work on /opt/airflow/dags/build_elt_with_dbt.py
[2025-04-20T21:44:16.050+0000] {processor.py:914} INFO - Processing file /opt/airflow/dags/build_elt_with_dbt.py for tasks to queue
[2025-04-20T21:44:16.053+0000] {logging_mixin.py:190} INFO - [2025-04-20T21:44:16.053+0000] {dagbag.py:587} INFO - Filling up the DagBag from /opt/airflow/dags/build_elt_with_dbt.py
[2025-04-20T21:44:16.094+0000] {logging_mixin.py:190} INFO - [2025-04-20T21:44:16.087+0000] {dagbag.py:386} ERROR - Failed to import: /opt/airflow/dags/build_elt_with_dbt.py
Traceback (most recent call last):
  File "/home/airflow/.local/lib/python3.12/site-packages/airflow/models/dagbag.py", line 382, in parse
    loader.exec_module(new_module)
  File "<frozen importlib._bootstrap_external>", line 995, in exec_module
  File "<frozen importlib._bootstrap>", line 488, in _call_with_frames_removed
  File "/opt/airflow/dags/build_elt_with_dbt.py", line 16, in <module>
    conn = BaseHook.get_connection('snowflake_conn')
           ^^^^^^^^^^^^^^^^^^^^^^^^^^^^^^^^^^^^^^^^^
  File "/home/airflow/.local/lib/python3.12/site-packages/airflow/hooks/base.py", line 83, in get_connection
    conn = Connection.get_connection_from_secrets(conn_id)
           ^^^^^^^^^^^^^^^^^^^^^^^^^^^^^^^^^^^^^^^^^^^^^^^
  File "/home/airflow/.local/lib/python3.12/site-packages/airflow/models/connection.py", line 537, in get_connection_from_secrets
    raise AirflowNotFoundException(f"The conn_id `{conn_id}` isn't defined")
airflow.exceptions.AirflowNotFoundException: The conn_id `snowflake_conn` isn't defined
[2025-04-20T21:44:16.096+0000] {processor.py:927} WARNING - No viable dags retrieved from /opt/airflow/dags/build_elt_with_dbt.py
[2025-04-20T21:44:16.110+0000] {processor.py:208} INFO - Processing /opt/airflow/dags/build_elt_with_dbt.py took 0.071 seconds
[2025-04-20T21:44:49.834+0000] {processor.py:186} INFO - Started process (PID=405) to work on /opt/airflow/dags/build_elt_with_dbt.py
[2025-04-20T21:44:49.836+0000] {processor.py:914} INFO - Processing file /opt/airflow/dags/build_elt_with_dbt.py for tasks to queue
[2025-04-20T21:44:49.844+0000] {logging_mixin.py:190} INFO - [2025-04-20T21:44:49.843+0000] {dagbag.py:587} INFO - Filling up the DagBag from /opt/airflow/dags/build_elt_with_dbt.py
[2025-04-20T21:44:49.918+0000] {logging_mixin.py:190} INFO - [2025-04-20T21:44:49.908+0000] {dagbag.py:386} ERROR - Failed to import: /opt/airflow/dags/build_elt_with_dbt.py
Traceback (most recent call last):
  File "/home/airflow/.local/lib/python3.12/site-packages/airflow/models/dagbag.py", line 382, in parse
    loader.exec_module(new_module)
  File "<frozen importlib._bootstrap_external>", line 995, in exec_module
  File "<frozen importlib._bootstrap>", line 488, in _call_with_frames_removed
  File "/opt/airflow/dags/build_elt_with_dbt.py", line 16, in <module>
    conn = BaseHook.get_connection('snowflake_conn')
           ^^^^^^^^^^^^^^^^^^^^^^^^^^^^^^^^^^^^^^^^^
  File "/home/airflow/.local/lib/python3.12/site-packages/airflow/hooks/base.py", line 83, in get_connection
    conn = Connection.get_connection_from_secrets(conn_id)
           ^^^^^^^^^^^^^^^^^^^^^^^^^^^^^^^^^^^^^^^^^^^^^^^
  File "/home/airflow/.local/lib/python3.12/site-packages/airflow/models/connection.py", line 537, in get_connection_from_secrets
    raise AirflowNotFoundException(f"The conn_id `{conn_id}` isn't defined")
airflow.exceptions.AirflowNotFoundException: The conn_id `snowflake_conn` isn't defined
[2025-04-20T21:44:49.919+0000] {processor.py:927} WARNING - No viable dags retrieved from /opt/airflow/dags/build_elt_with_dbt.py
[2025-04-20T21:44:49.944+0000] {processor.py:208} INFO - Processing /opt/airflow/dags/build_elt_with_dbt.py took 0.126 seconds
[2025-04-20T21:45:20.443+0000] {processor.py:186} INFO - Started process (PID=421) to work on /opt/airflow/dags/build_elt_with_dbt.py
[2025-04-20T21:45:20.445+0000] {processor.py:914} INFO - Processing file /opt/airflow/dags/build_elt_with_dbt.py for tasks to queue
[2025-04-20T21:45:20.451+0000] {logging_mixin.py:190} INFO - [2025-04-20T21:45:20.451+0000] {dagbag.py:587} INFO - Filling up the DagBag from /opt/airflow/dags/build_elt_with_dbt.py
[2025-04-20T21:45:20.505+0000] {logging_mixin.py:190} INFO - [2025-04-20T21:45:20.498+0000] {dagbag.py:386} ERROR - Failed to import: /opt/airflow/dags/build_elt_with_dbt.py
Traceback (most recent call last):
  File "/home/airflow/.local/lib/python3.12/site-packages/airflow/models/dagbag.py", line 382, in parse
    loader.exec_module(new_module)
  File "<frozen importlib._bootstrap_external>", line 995, in exec_module
  File "<frozen importlib._bootstrap>", line 488, in _call_with_frames_removed
  File "/opt/airflow/dags/build_elt_with_dbt.py", line 16, in <module>
    conn = BaseHook.get_connection('snowflake_conn')
           ^^^^^^^^^^^^^^^^^^^^^^^^^^^^^^^^^^^^^^^^^
  File "/home/airflow/.local/lib/python3.12/site-packages/airflow/hooks/base.py", line 83, in get_connection
    conn = Connection.get_connection_from_secrets(conn_id)
           ^^^^^^^^^^^^^^^^^^^^^^^^^^^^^^^^^^^^^^^^^^^^^^^
  File "/home/airflow/.local/lib/python3.12/site-packages/airflow/models/connection.py", line 537, in get_connection_from_secrets
    raise AirflowNotFoundException(f"The conn_id `{conn_id}` isn't defined")
airflow.exceptions.AirflowNotFoundException: The conn_id `snowflake_conn` isn't defined
[2025-04-20T21:45:20.506+0000] {processor.py:927} WARNING - No viable dags retrieved from /opt/airflow/dags/build_elt_with_dbt.py
[2025-04-20T21:45:20.524+0000] {processor.py:208} INFO - Processing /opt/airflow/dags/build_elt_with_dbt.py took 0.095 seconds
[2025-04-20T21:45:50.949+0000] {processor.py:186} INFO - Started process (PID=439) to work on /opt/airflow/dags/build_elt_with_dbt.py
[2025-04-20T21:45:50.951+0000] {processor.py:914} INFO - Processing file /opt/airflow/dags/build_elt_with_dbt.py for tasks to queue
[2025-04-20T21:45:50.958+0000] {logging_mixin.py:190} INFO - [2025-04-20T21:45:50.957+0000] {dagbag.py:587} INFO - Filling up the DagBag from /opt/airflow/dags/build_elt_with_dbt.py
[2025-04-20T21:45:50.995+0000] {logging_mixin.py:190} INFO - [2025-04-20T21:45:50.991+0000] {dagbag.py:386} ERROR - Failed to import: /opt/airflow/dags/build_elt_with_dbt.py
Traceback (most recent call last):
  File "/home/airflow/.local/lib/python3.12/site-packages/airflow/models/dagbag.py", line 382, in parse
    loader.exec_module(new_module)
  File "<frozen importlib._bootstrap_external>", line 995, in exec_module
  File "<frozen importlib._bootstrap>", line 488, in _call_with_frames_removed
  File "/opt/airflow/dags/build_elt_with_dbt.py", line 16, in <module>
    conn = BaseHook.get_connection('snowflake_conn')
           ^^^^^^^^^^^^^^^^^^^^^^^^^^^^^^^^^^^^^^^^^
  File "/home/airflow/.local/lib/python3.12/site-packages/airflow/hooks/base.py", line 83, in get_connection
    conn = Connection.get_connection_from_secrets(conn_id)
           ^^^^^^^^^^^^^^^^^^^^^^^^^^^^^^^^^^^^^^^^^^^^^^^
  File "/home/airflow/.local/lib/python3.12/site-packages/airflow/models/connection.py", line 537, in get_connection_from_secrets
    raise AirflowNotFoundException(f"The conn_id `{conn_id}` isn't defined")
airflow.exceptions.AirflowNotFoundException: The conn_id `snowflake_conn` isn't defined
[2025-04-20T21:45:50.996+0000] {processor.py:927} WARNING - No viable dags retrieved from /opt/airflow/dags/build_elt_with_dbt.py
[2025-04-20T21:45:51.007+0000] {processor.py:208} INFO - Processing /opt/airflow/dags/build_elt_with_dbt.py took 0.073 seconds
[2025-04-20T21:46:21.439+0000] {processor.py:186} INFO - Started process (PID=455) to work on /opt/airflow/dags/build_elt_with_dbt.py
[2025-04-20T21:46:21.440+0000] {processor.py:914} INFO - Processing file /opt/airflow/dags/build_elt_with_dbt.py for tasks to queue
[2025-04-20T21:46:21.443+0000] {logging_mixin.py:190} INFO - [2025-04-20T21:46:21.442+0000] {dagbag.py:587} INFO - Filling up the DagBag from /opt/airflow/dags/build_elt_with_dbt.py
[2025-04-20T21:46:21.472+0000] {logging_mixin.py:190} INFO - [2025-04-20T21:46:21.468+0000] {dagbag.py:386} ERROR - Failed to import: /opt/airflow/dags/build_elt_with_dbt.py
Traceback (most recent call last):
  File "/home/airflow/.local/lib/python3.12/site-packages/airflow/models/dagbag.py", line 382, in parse
    loader.exec_module(new_module)
  File "<frozen importlib._bootstrap_external>", line 995, in exec_module
  File "<frozen importlib._bootstrap>", line 488, in _call_with_frames_removed
  File "/opt/airflow/dags/build_elt_with_dbt.py", line 16, in <module>
    conn = BaseHook.get_connection('snowflake_conn')
           ^^^^^^^^^^^^^^^^^^^^^^^^^^^^^^^^^^^^^^^^^
  File "/home/airflow/.local/lib/python3.12/site-packages/airflow/hooks/base.py", line 83, in get_connection
    conn = Connection.get_connection_from_secrets(conn_id)
           ^^^^^^^^^^^^^^^^^^^^^^^^^^^^^^^^^^^^^^^^^^^^^^^
  File "/home/airflow/.local/lib/python3.12/site-packages/airflow/models/connection.py", line 537, in get_connection_from_secrets
    raise AirflowNotFoundException(f"The conn_id `{conn_id}` isn't defined")
airflow.exceptions.AirflowNotFoundException: The conn_id `snowflake_conn` isn't defined
[2025-04-20T21:46:21.473+0000] {processor.py:927} WARNING - No viable dags retrieved from /opt/airflow/dags/build_elt_with_dbt.py
[2025-04-20T21:46:21.484+0000] {processor.py:208} INFO - Processing /opt/airflow/dags/build_elt_with_dbt.py took 0.052 seconds
[2025-04-20T21:46:51.949+0000] {processor.py:186} INFO - Started process (PID=471) to work on /opt/airflow/dags/build_elt_with_dbt.py
[2025-04-20T21:46:51.952+0000] {processor.py:914} INFO - Processing file /opt/airflow/dags/build_elt_with_dbt.py for tasks to queue
[2025-04-20T21:46:51.960+0000] {logging_mixin.py:190} INFO - [2025-04-20T21:46:51.959+0000] {dagbag.py:587} INFO - Filling up the DagBag from /opt/airflow/dags/build_elt_with_dbt.py
[2025-04-20T21:46:52.032+0000] {logging_mixin.py:190} INFO - [2025-04-20T21:46:52.023+0000] {dagbag.py:386} ERROR - Failed to import: /opt/airflow/dags/build_elt_with_dbt.py
Traceback (most recent call last):
  File "/home/airflow/.local/lib/python3.12/site-packages/airflow/models/dagbag.py", line 382, in parse
    loader.exec_module(new_module)
  File "<frozen importlib._bootstrap_external>", line 995, in exec_module
  File "<frozen importlib._bootstrap>", line 488, in _call_with_frames_removed
  File "/opt/airflow/dags/build_elt_with_dbt.py", line 16, in <module>
    conn = BaseHook.get_connection('snowflake_conn')
           ^^^^^^^^^^^^^^^^^^^^^^^^^^^^^^^^^^^^^^^^^
  File "/home/airflow/.local/lib/python3.12/site-packages/airflow/hooks/base.py", line 83, in get_connection
    conn = Connection.get_connection_from_secrets(conn_id)
           ^^^^^^^^^^^^^^^^^^^^^^^^^^^^^^^^^^^^^^^^^^^^^^^
  File "/home/airflow/.local/lib/python3.12/site-packages/airflow/models/connection.py", line 537, in get_connection_from_secrets
    raise AirflowNotFoundException(f"The conn_id `{conn_id}` isn't defined")
airflow.exceptions.AirflowNotFoundException: The conn_id `snowflake_conn` isn't defined
[2025-04-20T21:46:52.034+0000] {processor.py:927} WARNING - No viable dags retrieved from /opt/airflow/dags/build_elt_with_dbt.py
[2025-04-20T21:46:52.061+0000] {processor.py:208} INFO - Processing /opt/airflow/dags/build_elt_with_dbt.py took 0.135 seconds
[2025-04-20T21:47:22.556+0000] {processor.py:186} INFO - Started process (PID=487) to work on /opt/airflow/dags/build_elt_with_dbt.py
[2025-04-20T21:47:22.558+0000] {processor.py:914} INFO - Processing file /opt/airflow/dags/build_elt_with_dbt.py for tasks to queue
[2025-04-20T21:47:22.562+0000] {logging_mixin.py:190} INFO - [2025-04-20T21:47:22.561+0000] {dagbag.py:587} INFO - Filling up the DagBag from /opt/airflow/dags/build_elt_with_dbt.py
[2025-04-20T21:47:22.605+0000] {logging_mixin.py:190} INFO - [2025-04-20T21:47:22.598+0000] {dagbag.py:386} ERROR - Failed to import: /opt/airflow/dags/build_elt_with_dbt.py
Traceback (most recent call last):
  File "/home/airflow/.local/lib/python3.12/site-packages/airflow/models/dagbag.py", line 382, in parse
    loader.exec_module(new_module)
  File "<frozen importlib._bootstrap_external>", line 995, in exec_module
  File "<frozen importlib._bootstrap>", line 488, in _call_with_frames_removed
  File "/opt/airflow/dags/build_elt_with_dbt.py", line 16, in <module>
    conn = BaseHook.get_connection('snowflake_conn')
           ^^^^^^^^^^^^^^^^^^^^^^^^^^^^^^^^^^^^^^^^^
  File "/home/airflow/.local/lib/python3.12/site-packages/airflow/hooks/base.py", line 83, in get_connection
    conn = Connection.get_connection_from_secrets(conn_id)
           ^^^^^^^^^^^^^^^^^^^^^^^^^^^^^^^^^^^^^^^^^^^^^^^
  File "/home/airflow/.local/lib/python3.12/site-packages/airflow/models/connection.py", line 537, in get_connection_from_secrets
    raise AirflowNotFoundException(f"The conn_id `{conn_id}` isn't defined")
airflow.exceptions.AirflowNotFoundException: The conn_id `snowflake_conn` isn't defined
[2025-04-20T21:47:22.606+0000] {processor.py:927} WARNING - No viable dags retrieved from /opt/airflow/dags/build_elt_with_dbt.py
[2025-04-20T21:47:22.622+0000] {processor.py:208} INFO - Processing /opt/airflow/dags/build_elt_with_dbt.py took 0.077 seconds
[2025-04-20T21:47:53.090+0000] {processor.py:186} INFO - Started process (PID=503) to work on /opt/airflow/dags/build_elt_with_dbt.py
[2025-04-20T21:47:53.092+0000] {processor.py:914} INFO - Processing file /opt/airflow/dags/build_elt_with_dbt.py for tasks to queue
[2025-04-20T21:47:53.097+0000] {logging_mixin.py:190} INFO - [2025-04-20T21:47:53.096+0000] {dagbag.py:587} INFO - Filling up the DagBag from /opt/airflow/dags/build_elt_with_dbt.py
[2025-04-20T21:47:53.144+0000] {logging_mixin.py:190} INFO - [2025-04-20T21:47:53.138+0000] {dagbag.py:386} ERROR - Failed to import: /opt/airflow/dags/build_elt_with_dbt.py
Traceback (most recent call last):
  File "/home/airflow/.local/lib/python3.12/site-packages/airflow/models/dagbag.py", line 382, in parse
    loader.exec_module(new_module)
  File "<frozen importlib._bootstrap_external>", line 995, in exec_module
  File "<frozen importlib._bootstrap>", line 488, in _call_with_frames_removed
  File "/opt/airflow/dags/build_elt_with_dbt.py", line 16, in <module>
    conn = BaseHook.get_connection('snowflake_conn')
           ^^^^^^^^^^^^^^^^^^^^^^^^^^^^^^^^^^^^^^^^^
  File "/home/airflow/.local/lib/python3.12/site-packages/airflow/hooks/base.py", line 83, in get_connection
    conn = Connection.get_connection_from_secrets(conn_id)
           ^^^^^^^^^^^^^^^^^^^^^^^^^^^^^^^^^^^^^^^^^^^^^^^
  File "/home/airflow/.local/lib/python3.12/site-packages/airflow/models/connection.py", line 537, in get_connection_from_secrets
    raise AirflowNotFoundException(f"The conn_id `{conn_id}` isn't defined")
airflow.exceptions.AirflowNotFoundException: The conn_id `snowflake_conn` isn't defined
[2025-04-20T21:47:53.146+0000] {processor.py:927} WARNING - No viable dags retrieved from /opt/airflow/dags/build_elt_with_dbt.py
[2025-04-20T21:47:53.163+0000] {processor.py:208} INFO - Processing /opt/airflow/dags/build_elt_with_dbt.py took 0.087 seconds
[2025-04-20T21:48:23.625+0000] {processor.py:186} INFO - Started process (PID=519) to work on /opt/airflow/dags/build_elt_with_dbt.py
[2025-04-20T21:48:23.627+0000] {processor.py:914} INFO - Processing file /opt/airflow/dags/build_elt_with_dbt.py for tasks to queue
[2025-04-20T21:48:23.631+0000] {logging_mixin.py:190} INFO - [2025-04-20T21:48:23.630+0000] {dagbag.py:587} INFO - Filling up the DagBag from /opt/airflow/dags/build_elt_with_dbt.py
[2025-04-20T21:48:23.671+0000] {logging_mixin.py:190} INFO - [2025-04-20T21:48:23.663+0000] {dagbag.py:386} ERROR - Failed to import: /opt/airflow/dags/build_elt_with_dbt.py
Traceback (most recent call last):
  File "/home/airflow/.local/lib/python3.12/site-packages/airflow/models/dagbag.py", line 382, in parse
    loader.exec_module(new_module)
  File "<frozen importlib._bootstrap_external>", line 995, in exec_module
  File "<frozen importlib._bootstrap>", line 488, in _call_with_frames_removed
  File "/opt/airflow/dags/build_elt_with_dbt.py", line 16, in <module>
    conn = BaseHook.get_connection('snowflake_conn')
           ^^^^^^^^^^^^^^^^^^^^^^^^^^^^^^^^^^^^^^^^^
  File "/home/airflow/.local/lib/python3.12/site-packages/airflow/hooks/base.py", line 83, in get_connection
    conn = Connection.get_connection_from_secrets(conn_id)
           ^^^^^^^^^^^^^^^^^^^^^^^^^^^^^^^^^^^^^^^^^^^^^^^
  File "/home/airflow/.local/lib/python3.12/site-packages/airflow/models/connection.py", line 537, in get_connection_from_secrets
    raise AirflowNotFoundException(f"The conn_id `{conn_id}` isn't defined")
airflow.exceptions.AirflowNotFoundException: The conn_id `snowflake_conn` isn't defined
[2025-04-20T21:48:23.672+0000] {processor.py:927} WARNING - No viable dags retrieved from /opt/airflow/dags/build_elt_with_dbt.py
[2025-04-20T21:48:23.683+0000] {processor.py:208} INFO - Processing /opt/airflow/dags/build_elt_with_dbt.py took 0.066 seconds
[2025-04-20T21:48:54.139+0000] {processor.py:186} INFO - Started process (PID=536) to work on /opt/airflow/dags/build_elt_with_dbt.py
[2025-04-20T21:48:54.140+0000] {processor.py:914} INFO - Processing file /opt/airflow/dags/build_elt_with_dbt.py for tasks to queue
[2025-04-20T21:48:54.145+0000] {logging_mixin.py:190} INFO - [2025-04-20T21:48:54.145+0000] {dagbag.py:587} INFO - Filling up the DagBag from /opt/airflow/dags/build_elt_with_dbt.py
[2025-04-20T21:48:54.190+0000] {logging_mixin.py:190} INFO - [2025-04-20T21:48:54.183+0000] {dagbag.py:386} ERROR - Failed to import: /opt/airflow/dags/build_elt_with_dbt.py
Traceback (most recent call last):
  File "/home/airflow/.local/lib/python3.12/site-packages/airflow/models/dagbag.py", line 382, in parse
    loader.exec_module(new_module)
  File "<frozen importlib._bootstrap_external>", line 995, in exec_module
  File "<frozen importlib._bootstrap>", line 488, in _call_with_frames_removed
  File "/opt/airflow/dags/build_elt_with_dbt.py", line 16, in <module>
    conn = BaseHook.get_connection('snowflake_conn')
           ^^^^^^^^^^^^^^^^^^^^^^^^^^^^^^^^^^^^^^^^^
  File "/home/airflow/.local/lib/python3.12/site-packages/airflow/hooks/base.py", line 83, in get_connection
    conn = Connection.get_connection_from_secrets(conn_id)
           ^^^^^^^^^^^^^^^^^^^^^^^^^^^^^^^^^^^^^^^^^^^^^^^
  File "/home/airflow/.local/lib/python3.12/site-packages/airflow/models/connection.py", line 537, in get_connection_from_secrets
    raise AirflowNotFoundException(f"The conn_id `{conn_id}` isn't defined")
airflow.exceptions.AirflowNotFoundException: The conn_id `snowflake_conn` isn't defined
[2025-04-20T21:48:54.191+0000] {processor.py:927} WARNING - No viable dags retrieved from /opt/airflow/dags/build_elt_with_dbt.py
[2025-04-20T21:48:54.208+0000] {processor.py:208} INFO - Processing /opt/airflow/dags/build_elt_with_dbt.py took 0.080 seconds
[2025-04-20T21:49:24.754+0000] {processor.py:186} INFO - Started process (PID=553) to work on /opt/airflow/dags/build_elt_with_dbt.py
[2025-04-20T21:49:24.758+0000] {processor.py:914} INFO - Processing file /opt/airflow/dags/build_elt_with_dbt.py for tasks to queue
[2025-04-20T21:49:24.765+0000] {logging_mixin.py:190} INFO - [2025-04-20T21:49:24.764+0000] {dagbag.py:587} INFO - Filling up the DagBag from /opt/airflow/dags/build_elt_with_dbt.py
[2025-04-20T21:49:24.822+0000] {logging_mixin.py:190} INFO - [2025-04-20T21:49:24.813+0000] {dagbag.py:386} ERROR - Failed to import: /opt/airflow/dags/build_elt_with_dbt.py
Traceback (most recent call last):
  File "/home/airflow/.local/lib/python3.12/site-packages/airflow/models/dagbag.py", line 382, in parse
    loader.exec_module(new_module)
  File "<frozen importlib._bootstrap_external>", line 995, in exec_module
  File "<frozen importlib._bootstrap>", line 488, in _call_with_frames_removed
  File "/opt/airflow/dags/build_elt_with_dbt.py", line 16, in <module>
    conn = BaseHook.get_connection('snowflake_conn')
           ^^^^^^^^^^^^^^^^^^^^^^^^^^^^^^^^^^^^^^^^^
  File "/home/airflow/.local/lib/python3.12/site-packages/airflow/hooks/base.py", line 83, in get_connection
    conn = Connection.get_connection_from_secrets(conn_id)
           ^^^^^^^^^^^^^^^^^^^^^^^^^^^^^^^^^^^^^^^^^^^^^^^
  File "/home/airflow/.local/lib/python3.12/site-packages/airflow/models/connection.py", line 537, in get_connection_from_secrets
    raise AirflowNotFoundException(f"The conn_id `{conn_id}` isn't defined")
airflow.exceptions.AirflowNotFoundException: The conn_id `snowflake_conn` isn't defined
[2025-04-20T21:49:24.824+0000] {processor.py:927} WARNING - No viable dags retrieved from /opt/airflow/dags/build_elt_with_dbt.py
[2025-04-20T21:49:24.849+0000] {processor.py:208} INFO - Processing /opt/airflow/dags/build_elt_with_dbt.py took 0.112 seconds
[2025-04-20T21:49:55.286+0000] {processor.py:186} INFO - Started process (PID=569) to work on /opt/airflow/dags/build_elt_with_dbt.py
[2025-04-20T21:49:55.288+0000] {processor.py:914} INFO - Processing file /opt/airflow/dags/build_elt_with_dbt.py for tasks to queue
[2025-04-20T21:49:55.292+0000] {logging_mixin.py:190} INFO - [2025-04-20T21:49:55.291+0000] {dagbag.py:587} INFO - Filling up the DagBag from /opt/airflow/dags/build_elt_with_dbt.py
[2025-04-20T21:49:55.346+0000] {logging_mixin.py:190} INFO - [2025-04-20T21:49:55.339+0000] {dagbag.py:386} ERROR - Failed to import: /opt/airflow/dags/build_elt_with_dbt.py
Traceback (most recent call last):
  File "/home/airflow/.local/lib/python3.12/site-packages/airflow/models/dagbag.py", line 382, in parse
    loader.exec_module(new_module)
  File "<frozen importlib._bootstrap_external>", line 995, in exec_module
  File "<frozen importlib._bootstrap>", line 488, in _call_with_frames_removed
  File "/opt/airflow/dags/build_elt_with_dbt.py", line 16, in <module>
    conn = BaseHook.get_connection('snowflake_conn')
           ^^^^^^^^^^^^^^^^^^^^^^^^^^^^^^^^^^^^^^^^^
  File "/home/airflow/.local/lib/python3.12/site-packages/airflow/hooks/base.py", line 83, in get_connection
    conn = Connection.get_connection_from_secrets(conn_id)
           ^^^^^^^^^^^^^^^^^^^^^^^^^^^^^^^^^^^^^^^^^^^^^^^
  File "/home/airflow/.local/lib/python3.12/site-packages/airflow/models/connection.py", line 537, in get_connection_from_secrets
    raise AirflowNotFoundException(f"The conn_id `{conn_id}` isn't defined")
airflow.exceptions.AirflowNotFoundException: The conn_id `snowflake_conn` isn't defined
[2025-04-20T21:49:55.348+0000] {processor.py:927} WARNING - No viable dags retrieved from /opt/airflow/dags/build_elt_with_dbt.py
[2025-04-20T21:49:55.364+0000] {processor.py:208} INFO - Processing /opt/airflow/dags/build_elt_with_dbt.py took 0.088 seconds
[2025-04-20T21:50:25.804+0000] {processor.py:186} INFO - Started process (PID=585) to work on /opt/airflow/dags/build_elt_with_dbt.py
[2025-04-20T21:50:25.805+0000] {processor.py:914} INFO - Processing file /opt/airflow/dags/build_elt_with_dbt.py for tasks to queue
[2025-04-20T21:50:25.808+0000] {logging_mixin.py:190} INFO - [2025-04-20T21:50:25.808+0000] {dagbag.py:587} INFO - Filling up the DagBag from /opt/airflow/dags/build_elt_with_dbt.py
[2025-04-20T21:50:25.844+0000] {logging_mixin.py:190} INFO - [2025-04-20T21:50:25.838+0000] {dagbag.py:386} ERROR - Failed to import: /opt/airflow/dags/build_elt_with_dbt.py
Traceback (most recent call last):
  File "/home/airflow/.local/lib/python3.12/site-packages/airflow/models/dagbag.py", line 382, in parse
    loader.exec_module(new_module)
  File "<frozen importlib._bootstrap_external>", line 995, in exec_module
  File "<frozen importlib._bootstrap>", line 488, in _call_with_frames_removed
  File "/opt/airflow/dags/build_elt_with_dbt.py", line 16, in <module>
    conn = BaseHook.get_connection('snowflake_conn')
           ^^^^^^^^^^^^^^^^^^^^^^^^^^^^^^^^^^^^^^^^^
  File "/home/airflow/.local/lib/python3.12/site-packages/airflow/hooks/base.py", line 83, in get_connection
    conn = Connection.get_connection_from_secrets(conn_id)
           ^^^^^^^^^^^^^^^^^^^^^^^^^^^^^^^^^^^^^^^^^^^^^^^
  File "/home/airflow/.local/lib/python3.12/site-packages/airflow/models/connection.py", line 537, in get_connection_from_secrets
    raise AirflowNotFoundException(f"The conn_id `{conn_id}` isn't defined")
airflow.exceptions.AirflowNotFoundException: The conn_id `snowflake_conn` isn't defined
[2025-04-20T21:50:25.844+0000] {processor.py:927} WARNING - No viable dags retrieved from /opt/airflow/dags/build_elt_with_dbt.py
[2025-04-20T21:50:25.860+0000] {processor.py:208} INFO - Processing /opt/airflow/dags/build_elt_with_dbt.py took 0.063 seconds
[2025-04-20T21:50:56.334+0000] {processor.py:186} INFO - Started process (PID=601) to work on /opt/airflow/dags/build_elt_with_dbt.py
[2025-04-20T21:50:56.337+0000] {processor.py:914} INFO - Processing file /opt/airflow/dags/build_elt_with_dbt.py for tasks to queue
[2025-04-20T21:50:56.344+0000] {logging_mixin.py:190} INFO - [2025-04-20T21:50:56.342+0000] {dagbag.py:587} INFO - Filling up the DagBag from /opt/airflow/dags/build_elt_with_dbt.py
[2025-04-20T21:50:56.382+0000] {logging_mixin.py:190} INFO - [2025-04-20T21:50:56.378+0000] {dagbag.py:386} ERROR - Failed to import: /opt/airflow/dags/build_elt_with_dbt.py
Traceback (most recent call last):
  File "/home/airflow/.local/lib/python3.12/site-packages/airflow/models/dagbag.py", line 382, in parse
    loader.exec_module(new_module)
  File "<frozen importlib._bootstrap_external>", line 995, in exec_module
  File "<frozen importlib._bootstrap>", line 488, in _call_with_frames_removed
  File "/opt/airflow/dags/build_elt_with_dbt.py", line 16, in <module>
    conn = BaseHook.get_connection('snowflake_conn')
           ^^^^^^^^^^^^^^^^^^^^^^^^^^^^^^^^^^^^^^^^^
  File "/home/airflow/.local/lib/python3.12/site-packages/airflow/hooks/base.py", line 83, in get_connection
    conn = Connection.get_connection_from_secrets(conn_id)
           ^^^^^^^^^^^^^^^^^^^^^^^^^^^^^^^^^^^^^^^^^^^^^^^
  File "/home/airflow/.local/lib/python3.12/site-packages/airflow/models/connection.py", line 537, in get_connection_from_secrets
    raise AirflowNotFoundException(f"The conn_id `{conn_id}` isn't defined")
airflow.exceptions.AirflowNotFoundException: The conn_id `snowflake_conn` isn't defined
[2025-04-20T21:50:56.383+0000] {processor.py:927} WARNING - No viable dags retrieved from /opt/airflow/dags/build_elt_with_dbt.py
[2025-04-20T21:50:56.395+0000] {processor.py:208} INFO - Processing /opt/airflow/dags/build_elt_with_dbt.py took 0.075 seconds
[2025-04-20T21:51:26.872+0000] {processor.py:186} INFO - Started process (PID=617) to work on /opt/airflow/dags/build_elt_with_dbt.py
[2025-04-20T21:51:26.875+0000] {processor.py:914} INFO - Processing file /opt/airflow/dags/build_elt_with_dbt.py for tasks to queue
[2025-04-20T21:51:26.879+0000] {logging_mixin.py:190} INFO - [2025-04-20T21:51:26.878+0000] {dagbag.py:587} INFO - Filling up the DagBag from /opt/airflow/dags/build_elt_with_dbt.py
[2025-04-20T21:51:26.926+0000] {logging_mixin.py:190} INFO - [2025-04-20T21:51:26.919+0000] {dagbag.py:386} ERROR - Failed to import: /opt/airflow/dags/build_elt_with_dbt.py
Traceback (most recent call last):
  File "/home/airflow/.local/lib/python3.12/site-packages/airflow/models/dagbag.py", line 382, in parse
    loader.exec_module(new_module)
  File "<frozen importlib._bootstrap_external>", line 995, in exec_module
  File "<frozen importlib._bootstrap>", line 488, in _call_with_frames_removed
  File "/opt/airflow/dags/build_elt_with_dbt.py", line 16, in <module>
    conn = BaseHook.get_connection('snowflake_conn')
           ^^^^^^^^^^^^^^^^^^^^^^^^^^^^^^^^^^^^^^^^^
  File "/home/airflow/.local/lib/python3.12/site-packages/airflow/hooks/base.py", line 83, in get_connection
    conn = Connection.get_connection_from_secrets(conn_id)
           ^^^^^^^^^^^^^^^^^^^^^^^^^^^^^^^^^^^^^^^^^^^^^^^
  File "/home/airflow/.local/lib/python3.12/site-packages/airflow/models/connection.py", line 537, in get_connection_from_secrets
    raise AirflowNotFoundException(f"The conn_id `{conn_id}` isn't defined")
airflow.exceptions.AirflowNotFoundException: The conn_id `snowflake_conn` isn't defined
[2025-04-20T21:51:26.927+0000] {processor.py:927} WARNING - No viable dags retrieved from /opt/airflow/dags/build_elt_with_dbt.py
[2025-04-20T21:51:26.943+0000] {processor.py:208} INFO - Processing /opt/airflow/dags/build_elt_with_dbt.py took 0.081 seconds
[2025-04-20T21:51:57.408+0000] {processor.py:186} INFO - Started process (PID=633) to work on /opt/airflow/dags/build_elt_with_dbt.py
[2025-04-20T21:51:57.409+0000] {processor.py:914} INFO - Processing file /opt/airflow/dags/build_elt_with_dbt.py for tasks to queue
[2025-04-20T21:51:57.416+0000] {logging_mixin.py:190} INFO - [2025-04-20T21:51:57.415+0000] {dagbag.py:587} INFO - Filling up the DagBag from /opt/airflow/dags/build_elt_with_dbt.py
[2025-04-20T21:51:57.452+0000] {logging_mixin.py:190} INFO - [2025-04-20T21:51:57.446+0000] {dagbag.py:386} ERROR - Failed to import: /opt/airflow/dags/build_elt_with_dbt.py
Traceback (most recent call last):
  File "/home/airflow/.local/lib/python3.12/site-packages/airflow/models/dagbag.py", line 382, in parse
    loader.exec_module(new_module)
  File "<frozen importlib._bootstrap_external>", line 995, in exec_module
  File "<frozen importlib._bootstrap>", line 488, in _call_with_frames_removed
  File "/opt/airflow/dags/build_elt_with_dbt.py", line 16, in <module>
    conn = BaseHook.get_connection('snowflake_conn')
           ^^^^^^^^^^^^^^^^^^^^^^^^^^^^^^^^^^^^^^^^^
  File "/home/airflow/.local/lib/python3.12/site-packages/airflow/hooks/base.py", line 83, in get_connection
    conn = Connection.get_connection_from_secrets(conn_id)
           ^^^^^^^^^^^^^^^^^^^^^^^^^^^^^^^^^^^^^^^^^^^^^^^
  File "/home/airflow/.local/lib/python3.12/site-packages/airflow/models/connection.py", line 537, in get_connection_from_secrets
    raise AirflowNotFoundException(f"The conn_id `{conn_id}` isn't defined")
airflow.exceptions.AirflowNotFoundException: The conn_id `snowflake_conn` isn't defined
[2025-04-20T21:51:57.453+0000] {processor.py:927} WARNING - No viable dags retrieved from /opt/airflow/dags/build_elt_with_dbt.py
[2025-04-20T21:51:57.465+0000] {processor.py:208} INFO - Processing /opt/airflow/dags/build_elt_with_dbt.py took 0.065 seconds
[2025-04-20T21:52:27.921+0000] {processor.py:186} INFO - Started process (PID=649) to work on /opt/airflow/dags/build_elt_with_dbt.py
[2025-04-20T21:52:27.922+0000] {processor.py:914} INFO - Processing file /opt/airflow/dags/build_elt_with_dbt.py for tasks to queue
[2025-04-20T21:52:27.925+0000] {logging_mixin.py:190} INFO - [2025-04-20T21:52:27.925+0000] {dagbag.py:587} INFO - Filling up the DagBag from /opt/airflow/dags/build_elt_with_dbt.py
[2025-04-20T21:52:27.974+0000] {logging_mixin.py:190} INFO - [2025-04-20T21:52:27.965+0000] {dagbag.py:386} ERROR - Failed to import: /opt/airflow/dags/build_elt_with_dbt.py
Traceback (most recent call last):
  File "/home/airflow/.local/lib/python3.12/site-packages/airflow/models/dagbag.py", line 382, in parse
    loader.exec_module(new_module)
  File "<frozen importlib._bootstrap_external>", line 995, in exec_module
  File "<frozen importlib._bootstrap>", line 488, in _call_with_frames_removed
  File "/opt/airflow/dags/build_elt_with_dbt.py", line 16, in <module>
    conn = BaseHook.get_connection('snowflake_conn')
           ^^^^^^^^^^^^^^^^^^^^^^^^^^^^^^^^^^^^^^^^^
  File "/home/airflow/.local/lib/python3.12/site-packages/airflow/hooks/base.py", line 83, in get_connection
    conn = Connection.get_connection_from_secrets(conn_id)
           ^^^^^^^^^^^^^^^^^^^^^^^^^^^^^^^^^^^^^^^^^^^^^^^
  File "/home/airflow/.local/lib/python3.12/site-packages/airflow/models/connection.py", line 537, in get_connection_from_secrets
    raise AirflowNotFoundException(f"The conn_id `{conn_id}` isn't defined")
airflow.exceptions.AirflowNotFoundException: The conn_id `snowflake_conn` isn't defined
[2025-04-20T21:52:27.975+0000] {processor.py:927} WARNING - No viable dags retrieved from /opt/airflow/dags/build_elt_with_dbt.py
[2025-04-20T21:52:27.989+0000] {processor.py:208} INFO - Processing /opt/airflow/dags/build_elt_with_dbt.py took 0.075 seconds
[2025-04-20T21:52:58.424+0000] {processor.py:186} INFO - Started process (PID=665) to work on /opt/airflow/dags/build_elt_with_dbt.py
[2025-04-20T21:52:58.426+0000] {processor.py:914} INFO - Processing file /opt/airflow/dags/build_elt_with_dbt.py for tasks to queue
[2025-04-20T21:52:58.430+0000] {logging_mixin.py:190} INFO - [2025-04-20T21:52:58.430+0000] {dagbag.py:587} INFO - Filling up the DagBag from /opt/airflow/dags/build_elt_with_dbt.py
[2025-04-20T21:52:58.478+0000] {logging_mixin.py:190} INFO - [2025-04-20T21:52:58.471+0000] {dagbag.py:386} ERROR - Failed to import: /opt/airflow/dags/build_elt_with_dbt.py
Traceback (most recent call last):
  File "/home/airflow/.local/lib/python3.12/site-packages/airflow/models/dagbag.py", line 382, in parse
    loader.exec_module(new_module)
  File "<frozen importlib._bootstrap_external>", line 995, in exec_module
  File "<frozen importlib._bootstrap>", line 488, in _call_with_frames_removed
  File "/opt/airflow/dags/build_elt_with_dbt.py", line 16, in <module>
    conn = BaseHook.get_connection('snowflake_conn')
           ^^^^^^^^^^^^^^^^^^^^^^^^^^^^^^^^^^^^^^^^^
  File "/home/airflow/.local/lib/python3.12/site-packages/airflow/hooks/base.py", line 83, in get_connection
    conn = Connection.get_connection_from_secrets(conn_id)
           ^^^^^^^^^^^^^^^^^^^^^^^^^^^^^^^^^^^^^^^^^^^^^^^
  File "/home/airflow/.local/lib/python3.12/site-packages/airflow/models/connection.py", line 537, in get_connection_from_secrets
    raise AirflowNotFoundException(f"The conn_id `{conn_id}` isn't defined")
airflow.exceptions.AirflowNotFoundException: The conn_id `snowflake_conn` isn't defined
[2025-04-20T21:52:58.480+0000] {processor.py:927} WARNING - No viable dags retrieved from /opt/airflow/dags/build_elt_with_dbt.py
[2025-04-20T21:52:58.496+0000] {processor.py:208} INFO - Processing /opt/airflow/dags/build_elt_with_dbt.py took 0.083 seconds
[2025-04-20T21:53:28.993+0000] {processor.py:186} INFO - Started process (PID=681) to work on /opt/airflow/dags/build_elt_with_dbt.py
[2025-04-20T21:53:28.995+0000] {processor.py:914} INFO - Processing file /opt/airflow/dags/build_elt_with_dbt.py for tasks to queue
[2025-04-20T21:53:29.000+0000] {logging_mixin.py:190} INFO - [2025-04-20T21:53:29.000+0000] {dagbag.py:587} INFO - Filling up the DagBag from /opt/airflow/dags/build_elt_with_dbt.py
[2025-04-20T21:53:29.037+0000] {logging_mixin.py:190} INFO - [2025-04-20T21:53:29.033+0000] {dagbag.py:386} ERROR - Failed to import: /opt/airflow/dags/build_elt_with_dbt.py
Traceback (most recent call last):
  File "/home/airflow/.local/lib/python3.12/site-packages/airflow/models/dagbag.py", line 382, in parse
    loader.exec_module(new_module)
  File "<frozen importlib._bootstrap_external>", line 995, in exec_module
  File "<frozen importlib._bootstrap>", line 488, in _call_with_frames_removed
  File "/opt/airflow/dags/build_elt_with_dbt.py", line 16, in <module>
    conn = BaseHook.get_connection('snowflake_conn')
           ^^^^^^^^^^^^^^^^^^^^^^^^^^^^^^^^^^^^^^^^^
  File "/home/airflow/.local/lib/python3.12/site-packages/airflow/hooks/base.py", line 83, in get_connection
    conn = Connection.get_connection_from_secrets(conn_id)
           ^^^^^^^^^^^^^^^^^^^^^^^^^^^^^^^^^^^^^^^^^^^^^^^
  File "/home/airflow/.local/lib/python3.12/site-packages/airflow/models/connection.py", line 537, in get_connection_from_secrets
    raise AirflowNotFoundException(f"The conn_id `{conn_id}` isn't defined")
airflow.exceptions.AirflowNotFoundException: The conn_id `snowflake_conn` isn't defined
[2025-04-20T21:53:29.038+0000] {processor.py:927} WARNING - No viable dags retrieved from /opt/airflow/dags/build_elt_with_dbt.py
[2025-04-20T21:53:29.049+0000] {processor.py:208} INFO - Processing /opt/airflow/dags/build_elt_with_dbt.py took 0.071 seconds
[2025-04-20T21:53:59.517+0000] {processor.py:186} INFO - Started process (PID=697) to work on /opt/airflow/dags/build_elt_with_dbt.py
[2025-04-20T21:53:59.520+0000] {processor.py:914} INFO - Processing file /opt/airflow/dags/build_elt_with_dbt.py for tasks to queue
[2025-04-20T21:53:59.525+0000] {logging_mixin.py:190} INFO - [2025-04-20T21:53:59.525+0000] {dagbag.py:587} INFO - Filling up the DagBag from /opt/airflow/dags/build_elt_with_dbt.py
[2025-04-20T21:53:59.595+0000] {logging_mixin.py:190} INFO - [2025-04-20T21:53:59.584+0000] {dagbag.py:386} ERROR - Failed to import: /opt/airflow/dags/build_elt_with_dbt.py
Traceback (most recent call last):
  File "/home/airflow/.local/lib/python3.12/site-packages/airflow/models/dagbag.py", line 382, in parse
    loader.exec_module(new_module)
  File "<frozen importlib._bootstrap_external>", line 995, in exec_module
  File "<frozen importlib._bootstrap>", line 488, in _call_with_frames_removed
  File "/opt/airflow/dags/build_elt_with_dbt.py", line 16, in <module>
    conn = BaseHook.get_connection('snowflake_conn')
           ^^^^^^^^^^^^^^^^^^^^^^^^^^^^^^^^^^^^^^^^^
  File "/home/airflow/.local/lib/python3.12/site-packages/airflow/hooks/base.py", line 83, in get_connection
    conn = Connection.get_connection_from_secrets(conn_id)
           ^^^^^^^^^^^^^^^^^^^^^^^^^^^^^^^^^^^^^^^^^^^^^^^
  File "/home/airflow/.local/lib/python3.12/site-packages/airflow/models/connection.py", line 537, in get_connection_from_secrets
    raise AirflowNotFoundException(f"The conn_id `{conn_id}` isn't defined")
airflow.exceptions.AirflowNotFoundException: The conn_id `snowflake_conn` isn't defined
[2025-04-20T21:53:59.597+0000] {processor.py:927} WARNING - No viable dags retrieved from /opt/airflow/dags/build_elt_with_dbt.py
[2025-04-20T21:53:59.621+0000] {processor.py:208} INFO - Processing /opt/airflow/dags/build_elt_with_dbt.py took 0.119 seconds
[2025-04-20T21:54:30.212+0000] {processor.py:186} INFO - Started process (PID=713) to work on /opt/airflow/dags/build_elt_with_dbt.py
[2025-04-20T21:54:30.214+0000] {processor.py:914} INFO - Processing file /opt/airflow/dags/build_elt_with_dbt.py for tasks to queue
[2025-04-20T21:54:30.220+0000] {logging_mixin.py:190} INFO - [2025-04-20T21:54:30.219+0000] {dagbag.py:587} INFO - Filling up the DagBag from /opt/airflow/dags/build_elt_with_dbt.py
[2025-04-20T21:54:30.295+0000] {logging_mixin.py:190} INFO - [2025-04-20T21:54:30.282+0000] {dagbag.py:386} ERROR - Failed to import: /opt/airflow/dags/build_elt_with_dbt.py
Traceback (most recent call last):
  File "/home/airflow/.local/lib/python3.12/site-packages/airflow/models/dagbag.py", line 382, in parse
    loader.exec_module(new_module)
  File "<frozen importlib._bootstrap_external>", line 995, in exec_module
  File "<frozen importlib._bootstrap>", line 488, in _call_with_frames_removed
  File "/opt/airflow/dags/build_elt_with_dbt.py", line 16, in <module>
    conn = BaseHook.get_connection('snowflake_conn')
           ^^^^^^^^^^^^^^^^^^^^^^^^^^^^^^^^^^^^^^^^^
  File "/home/airflow/.local/lib/python3.12/site-packages/airflow/hooks/base.py", line 83, in get_connection
    conn = Connection.get_connection_from_secrets(conn_id)
           ^^^^^^^^^^^^^^^^^^^^^^^^^^^^^^^^^^^^^^^^^^^^^^^
  File "/home/airflow/.local/lib/python3.12/site-packages/airflow/models/connection.py", line 537, in get_connection_from_secrets
    raise AirflowNotFoundException(f"The conn_id `{conn_id}` isn't defined")
airflow.exceptions.AirflowNotFoundException: The conn_id `snowflake_conn` isn't defined
[2025-04-20T21:54:30.298+0000] {processor.py:927} WARNING - No viable dags retrieved from /opt/airflow/dags/build_elt_with_dbt.py
[2025-04-20T21:54:30.322+0000] {processor.py:208} INFO - Processing /opt/airflow/dags/build_elt_with_dbt.py took 0.122 seconds
[2025-04-20T21:55:00.656+0000] {processor.py:186} INFO - Started process (PID=729) to work on /opt/airflow/dags/build_elt_with_dbt.py
[2025-04-20T21:55:00.658+0000] {processor.py:914} INFO - Processing file /opt/airflow/dags/build_elt_with_dbt.py for tasks to queue
[2025-04-20T21:55:00.663+0000] {logging_mixin.py:190} INFO - [2025-04-20T21:55:00.662+0000] {dagbag.py:587} INFO - Filling up the DagBag from /opt/airflow/dags/build_elt_with_dbt.py
[2025-04-20T21:55:00.724+0000] {logging_mixin.py:190} INFO - [2025-04-20T21:55:00.715+0000] {dagbag.py:386} ERROR - Failed to import: /opt/airflow/dags/build_elt_with_dbt.py
Traceback (most recent call last):
  File "/home/airflow/.local/lib/python3.12/site-packages/airflow/models/dagbag.py", line 382, in parse
    loader.exec_module(new_module)
  File "<frozen importlib._bootstrap_external>", line 995, in exec_module
  File "<frozen importlib._bootstrap>", line 488, in _call_with_frames_removed
  File "/opt/airflow/dags/build_elt_with_dbt.py", line 16, in <module>
    conn = BaseHook.get_connection('snowflake_conn')
           ^^^^^^^^^^^^^^^^^^^^^^^^^^^^^^^^^^^^^^^^^
  File "/home/airflow/.local/lib/python3.12/site-packages/airflow/hooks/base.py", line 83, in get_connection
    conn = Connection.get_connection_from_secrets(conn_id)
           ^^^^^^^^^^^^^^^^^^^^^^^^^^^^^^^^^^^^^^^^^^^^^^^
  File "/home/airflow/.local/lib/python3.12/site-packages/airflow/models/connection.py", line 537, in get_connection_from_secrets
    raise AirflowNotFoundException(f"The conn_id `{conn_id}` isn't defined")
airflow.exceptions.AirflowNotFoundException: The conn_id `snowflake_conn` isn't defined
[2025-04-20T21:55:00.727+0000] {processor.py:927} WARNING - No viable dags retrieved from /opt/airflow/dags/build_elt_with_dbt.py
[2025-04-20T21:55:00.747+0000] {processor.py:208} INFO - Processing /opt/airflow/dags/build_elt_with_dbt.py took 0.103 seconds
[2025-04-20T21:55:31.224+0000] {processor.py:186} INFO - Started process (PID=745) to work on /opt/airflow/dags/build_elt_with_dbt.py
[2025-04-20T21:55:31.228+0000] {processor.py:914} INFO - Processing file /opt/airflow/dags/build_elt_with_dbt.py for tasks to queue
[2025-04-20T21:55:31.237+0000] {logging_mixin.py:190} INFO - [2025-04-20T21:55:31.236+0000] {dagbag.py:587} INFO - Filling up the DagBag from /opt/airflow/dags/build_elt_with_dbt.py
[2025-04-20T21:55:31.266+0000] {logging_mixin.py:190} INFO - [2025-04-20T21:55:31.261+0000] {dagbag.py:386} ERROR - Failed to import: /opt/airflow/dags/build_elt_with_dbt.py
Traceback (most recent call last):
  File "/home/airflow/.local/lib/python3.12/site-packages/airflow/models/dagbag.py", line 382, in parse
    loader.exec_module(new_module)
  File "<frozen importlib._bootstrap_external>", line 995, in exec_module
  File "<frozen importlib._bootstrap>", line 488, in _call_with_frames_removed
  File "/opt/airflow/dags/build_elt_with_dbt.py", line 16, in <module>
    conn = BaseHook.get_connection('snowflake_conn')
           ^^^^^^^^^^^^^^^^^^^^^^^^^^^^^^^^^^^^^^^^^
  File "/home/airflow/.local/lib/python3.12/site-packages/airflow/hooks/base.py", line 83, in get_connection
    conn = Connection.get_connection_from_secrets(conn_id)
           ^^^^^^^^^^^^^^^^^^^^^^^^^^^^^^^^^^^^^^^^^^^^^^^
  File "/home/airflow/.local/lib/python3.12/site-packages/airflow/models/connection.py", line 537, in get_connection_from_secrets
    raise AirflowNotFoundException(f"The conn_id `{conn_id}` isn't defined")
airflow.exceptions.AirflowNotFoundException: The conn_id `snowflake_conn` isn't defined
[2025-04-20T21:55:31.267+0000] {processor.py:927} WARNING - No viable dags retrieved from /opt/airflow/dags/build_elt_with_dbt.py
[2025-04-20T21:55:31.277+0000] {processor.py:208} INFO - Processing /opt/airflow/dags/build_elt_with_dbt.py took 0.067 seconds
[2025-04-20T21:56:01.662+0000] {processor.py:186} INFO - Started process (PID=761) to work on /opt/airflow/dags/build_elt_with_dbt.py
[2025-04-20T21:56:01.663+0000] {processor.py:914} INFO - Processing file /opt/airflow/dags/build_elt_with_dbt.py for tasks to queue
[2025-04-20T21:56:01.667+0000] {logging_mixin.py:190} INFO - [2025-04-20T21:56:01.667+0000] {dagbag.py:587} INFO - Filling up the DagBag from /opt/airflow/dags/build_elt_with_dbt.py
[2025-04-20T21:56:01.717+0000] {logging_mixin.py:190} INFO - [2025-04-20T21:56:01.711+0000] {dagbag.py:386} ERROR - Failed to import: /opt/airflow/dags/build_elt_with_dbt.py
Traceback (most recent call last):
  File "/home/airflow/.local/lib/python3.12/site-packages/airflow/models/dagbag.py", line 382, in parse
    loader.exec_module(new_module)
  File "<frozen importlib._bootstrap_external>", line 995, in exec_module
  File "<frozen importlib._bootstrap>", line 488, in _call_with_frames_removed
  File "/opt/airflow/dags/build_elt_with_dbt.py", line 16, in <module>
    conn = BaseHook.get_connection('snowflake_conn')
           ^^^^^^^^^^^^^^^^^^^^^^^^^^^^^^^^^^^^^^^^^
  File "/home/airflow/.local/lib/python3.12/site-packages/airflow/hooks/base.py", line 83, in get_connection
    conn = Connection.get_connection_from_secrets(conn_id)
           ^^^^^^^^^^^^^^^^^^^^^^^^^^^^^^^^^^^^^^^^^^^^^^^
  File "/home/airflow/.local/lib/python3.12/site-packages/airflow/models/connection.py", line 537, in get_connection_from_secrets
    raise AirflowNotFoundException(f"The conn_id `{conn_id}` isn't defined")
airflow.exceptions.AirflowNotFoundException: The conn_id `snowflake_conn` isn't defined
[2025-04-20T21:56:01.718+0000] {processor.py:927} WARNING - No viable dags retrieved from /opt/airflow/dags/build_elt_with_dbt.py
[2025-04-20T21:56:01.735+0000] {processor.py:208} INFO - Processing /opt/airflow/dags/build_elt_with_dbt.py took 0.083 seconds
[2025-04-20T21:56:32.188+0000] {processor.py:186} INFO - Started process (PID=777) to work on /opt/airflow/dags/build_elt_with_dbt.py
[2025-04-20T21:56:32.189+0000] {processor.py:914} INFO - Processing file /opt/airflow/dags/build_elt_with_dbt.py for tasks to queue
[2025-04-20T21:56:32.193+0000] {logging_mixin.py:190} INFO - [2025-04-20T21:56:32.192+0000] {dagbag.py:587} INFO - Filling up the DagBag from /opt/airflow/dags/build_elt_with_dbt.py
[2025-04-20T21:56:32.226+0000] {logging_mixin.py:190} INFO - [2025-04-20T21:56:32.221+0000] {dagbag.py:386} ERROR - Failed to import: /opt/airflow/dags/build_elt_with_dbt.py
Traceback (most recent call last):
  File "/home/airflow/.local/lib/python3.12/site-packages/airflow/models/dagbag.py", line 382, in parse
    loader.exec_module(new_module)
  File "<frozen importlib._bootstrap_external>", line 995, in exec_module
  File "<frozen importlib._bootstrap>", line 488, in _call_with_frames_removed
  File "/opt/airflow/dags/build_elt_with_dbt.py", line 16, in <module>
    conn = BaseHook.get_connection('snowflake_conn')
           ^^^^^^^^^^^^^^^^^^^^^^^^^^^^^^^^^^^^^^^^^
  File "/home/airflow/.local/lib/python3.12/site-packages/airflow/hooks/base.py", line 83, in get_connection
    conn = Connection.get_connection_from_secrets(conn_id)
           ^^^^^^^^^^^^^^^^^^^^^^^^^^^^^^^^^^^^^^^^^^^^^^^
  File "/home/airflow/.local/lib/python3.12/site-packages/airflow/models/connection.py", line 537, in get_connection_from_secrets
    raise AirflowNotFoundException(f"The conn_id `{conn_id}` isn't defined")
airflow.exceptions.AirflowNotFoundException: The conn_id `snowflake_conn` isn't defined
[2025-04-20T21:56:32.227+0000] {processor.py:927} WARNING - No viable dags retrieved from /opt/airflow/dags/build_elt_with_dbt.py
[2025-04-20T21:56:32.240+0000] {processor.py:208} INFO - Processing /opt/airflow/dags/build_elt_with_dbt.py took 0.059 seconds
[2025-04-20T21:57:02.674+0000] {processor.py:186} INFO - Started process (PID=793) to work on /opt/airflow/dags/build_elt_with_dbt.py
[2025-04-20T21:57:02.676+0000] {processor.py:914} INFO - Processing file /opt/airflow/dags/build_elt_with_dbt.py for tasks to queue
[2025-04-20T21:57:02.682+0000] {logging_mixin.py:190} INFO - [2025-04-20T21:57:02.681+0000] {dagbag.py:587} INFO - Filling up the DagBag from /opt/airflow/dags/build_elt_with_dbt.py
[2025-04-20T21:57:02.748+0000] {logging_mixin.py:190} INFO - [2025-04-20T21:57:02.737+0000] {dagbag.py:386} ERROR - Failed to import: /opt/airflow/dags/build_elt_with_dbt.py
Traceback (most recent call last):
  File "/home/airflow/.local/lib/python3.12/site-packages/airflow/models/dagbag.py", line 382, in parse
    loader.exec_module(new_module)
  File "<frozen importlib._bootstrap_external>", line 995, in exec_module
  File "<frozen importlib._bootstrap>", line 488, in _call_with_frames_removed
  File "/opt/airflow/dags/build_elt_with_dbt.py", line 16, in <module>
    conn = BaseHook.get_connection('snowflake_conn')
           ^^^^^^^^^^^^^^^^^^^^^^^^^^^^^^^^^^^^^^^^^
  File "/home/airflow/.local/lib/python3.12/site-packages/airflow/hooks/base.py", line 83, in get_connection
    conn = Connection.get_connection_from_secrets(conn_id)
           ^^^^^^^^^^^^^^^^^^^^^^^^^^^^^^^^^^^^^^^^^^^^^^^
  File "/home/airflow/.local/lib/python3.12/site-packages/airflow/models/connection.py", line 537, in get_connection_from_secrets
    raise AirflowNotFoundException(f"The conn_id `{conn_id}` isn't defined")
airflow.exceptions.AirflowNotFoundException: The conn_id `snowflake_conn` isn't defined
[2025-04-20T21:57:02.750+0000] {processor.py:927} WARNING - No viable dags retrieved from /opt/airflow/dags/build_elt_with_dbt.py
[2025-04-20T21:57:02.773+0000] {processor.py:208} INFO - Processing /opt/airflow/dags/build_elt_with_dbt.py took 0.116 seconds
[2025-04-20T21:57:33.234+0000] {processor.py:186} INFO - Started process (PID=809) to work on /opt/airflow/dags/build_elt_with_dbt.py
[2025-04-20T21:57:33.236+0000] {processor.py:914} INFO - Processing file /opt/airflow/dags/build_elt_with_dbt.py for tasks to queue
[2025-04-20T21:57:33.239+0000] {logging_mixin.py:190} INFO - [2025-04-20T21:57:33.239+0000] {dagbag.py:587} INFO - Filling up the DagBag from /opt/airflow/dags/build_elt_with_dbt.py
[2025-04-20T21:57:33.287+0000] {logging_mixin.py:190} INFO - [2025-04-20T21:57:33.281+0000] {dagbag.py:386} ERROR - Failed to import: /opt/airflow/dags/build_elt_with_dbt.py
Traceback (most recent call last):
  File "/home/airflow/.local/lib/python3.12/site-packages/airflow/models/dagbag.py", line 382, in parse
    loader.exec_module(new_module)
  File "<frozen importlib._bootstrap_external>", line 995, in exec_module
  File "<frozen importlib._bootstrap>", line 488, in _call_with_frames_removed
  File "/opt/airflow/dags/build_elt_with_dbt.py", line 16, in <module>
    conn = BaseHook.get_connection('snowflake_conn')
           ^^^^^^^^^^^^^^^^^^^^^^^^^^^^^^^^^^^^^^^^^
  File "/home/airflow/.local/lib/python3.12/site-packages/airflow/hooks/base.py", line 83, in get_connection
    conn = Connection.get_connection_from_secrets(conn_id)
           ^^^^^^^^^^^^^^^^^^^^^^^^^^^^^^^^^^^^^^^^^^^^^^^
  File "/home/airflow/.local/lib/python3.12/site-packages/airflow/models/connection.py", line 537, in get_connection_from_secrets
    raise AirflowNotFoundException(f"The conn_id `{conn_id}` isn't defined")
airflow.exceptions.AirflowNotFoundException: The conn_id `snowflake_conn` isn't defined
[2025-04-20T21:57:33.288+0000] {processor.py:927} WARNING - No viable dags retrieved from /opt/airflow/dags/build_elt_with_dbt.py
[2025-04-20T21:57:33.304+0000] {processor.py:208} INFO - Processing /opt/airflow/dags/build_elt_with_dbt.py took 0.083 seconds
[2025-04-20T21:58:03.612+0000] {processor.py:186} INFO - Started process (PID=824) to work on /opt/airflow/dags/build_elt_with_dbt.py
[2025-04-20T21:58:03.614+0000] {processor.py:914} INFO - Processing file /opt/airflow/dags/build_elt_with_dbt.py for tasks to queue
[2025-04-20T21:58:03.618+0000] {logging_mixin.py:190} INFO - [2025-04-20T21:58:03.618+0000] {dagbag.py:587} INFO - Filling up the DagBag from /opt/airflow/dags/build_elt_with_dbt.py
[2025-04-20T21:58:03.652+0000] {logging_mixin.py:190} INFO - [2025-04-20T21:58:03.648+0000] {dagbag.py:386} ERROR - Failed to import: /opt/airflow/dags/build_elt_with_dbt.py
Traceback (most recent call last):
  File "/home/airflow/.local/lib/python3.12/site-packages/airflow/models/dagbag.py", line 382, in parse
    loader.exec_module(new_module)
  File "<frozen importlib._bootstrap_external>", line 995, in exec_module
  File "<frozen importlib._bootstrap>", line 488, in _call_with_frames_removed
  File "/opt/airflow/dags/build_elt_with_dbt.py", line 16, in <module>
    conn = BaseHook.get_connection('snowflake_conn')
           ^^^^^^^^^^^^^^^^^^^^^^^^^^^^^^^^^^^^^^^^^
  File "/home/airflow/.local/lib/python3.12/site-packages/airflow/hooks/base.py", line 83, in get_connection
    conn = Connection.get_connection_from_secrets(conn_id)
           ^^^^^^^^^^^^^^^^^^^^^^^^^^^^^^^^^^^^^^^^^^^^^^^
  File "/home/airflow/.local/lib/python3.12/site-packages/airflow/models/connection.py", line 537, in get_connection_from_secrets
    raise AirflowNotFoundException(f"The conn_id `{conn_id}` isn't defined")
airflow.exceptions.AirflowNotFoundException: The conn_id `snowflake_conn` isn't defined
[2025-04-20T21:58:03.652+0000] {processor.py:927} WARNING - No viable dags retrieved from /opt/airflow/dags/build_elt_with_dbt.py
[2025-04-20T21:58:03.663+0000] {processor.py:208} INFO - Processing /opt/airflow/dags/build_elt_with_dbt.py took 0.062 seconds
[2025-04-20T21:58:34.108+0000] {processor.py:186} INFO - Started process (PID=840) to work on /opt/airflow/dags/build_elt_with_dbt.py
[2025-04-20T21:58:34.110+0000] {processor.py:914} INFO - Processing file /opt/airflow/dags/build_elt_with_dbt.py for tasks to queue
[2025-04-20T21:58:34.113+0000] {logging_mixin.py:190} INFO - [2025-04-20T21:58:34.113+0000] {dagbag.py:587} INFO - Filling up the DagBag from /opt/airflow/dags/build_elt_with_dbt.py
[2025-04-20T21:58:34.138+0000] {logging_mixin.py:190} INFO - [2025-04-20T21:58:34.135+0000] {dagbag.py:386} ERROR - Failed to import: /opt/airflow/dags/build_elt_with_dbt.py
Traceback (most recent call last):
  File "/home/airflow/.local/lib/python3.12/site-packages/airflow/models/dagbag.py", line 382, in parse
    loader.exec_module(new_module)
  File "<frozen importlib._bootstrap_external>", line 995, in exec_module
  File "<frozen importlib._bootstrap>", line 488, in _call_with_frames_removed
  File "/opt/airflow/dags/build_elt_with_dbt.py", line 16, in <module>
    conn = BaseHook.get_connection('snowflake_conn')
           ^^^^^^^^^^^^^^^^^^^^^^^^^^^^^^^^^^^^^^^^^
  File "/home/airflow/.local/lib/python3.12/site-packages/airflow/hooks/base.py", line 83, in get_connection
    conn = Connection.get_connection_from_secrets(conn_id)
           ^^^^^^^^^^^^^^^^^^^^^^^^^^^^^^^^^^^^^^^^^^^^^^^
  File "/home/airflow/.local/lib/python3.12/site-packages/airflow/models/connection.py", line 537, in get_connection_from_secrets
    raise AirflowNotFoundException(f"The conn_id `{conn_id}` isn't defined")
airflow.exceptions.AirflowNotFoundException: The conn_id `snowflake_conn` isn't defined
[2025-04-20T21:58:34.139+0000] {processor.py:927} WARNING - No viable dags retrieved from /opt/airflow/dags/build_elt_with_dbt.py
[2025-04-20T21:58:34.148+0000] {processor.py:208} INFO - Processing /opt/airflow/dags/build_elt_with_dbt.py took 0.053 seconds
[2025-04-20T21:59:04.580+0000] {processor.py:186} INFO - Started process (PID=856) to work on /opt/airflow/dags/build_elt_with_dbt.py
[2025-04-20T21:59:04.581+0000] {processor.py:914} INFO - Processing file /opt/airflow/dags/build_elt_with_dbt.py for tasks to queue
[2025-04-20T21:59:04.584+0000] {logging_mixin.py:190} INFO - [2025-04-20T21:59:04.583+0000] {dagbag.py:587} INFO - Filling up the DagBag from /opt/airflow/dags/build_elt_with_dbt.py
[2025-04-20T21:59:04.629+0000] {logging_mixin.py:190} INFO - [2025-04-20T21:59:04.623+0000] {dagbag.py:386} ERROR - Failed to import: /opt/airflow/dags/build_elt_with_dbt.py
Traceback (most recent call last):
  File "/home/airflow/.local/lib/python3.12/site-packages/airflow/models/dagbag.py", line 382, in parse
    loader.exec_module(new_module)
  File "<frozen importlib._bootstrap_external>", line 995, in exec_module
  File "<frozen importlib._bootstrap>", line 488, in _call_with_frames_removed
  File "/opt/airflow/dags/build_elt_with_dbt.py", line 16, in <module>
    conn = BaseHook.get_connection('snowflake_conn')
           ^^^^^^^^^^^^^^^^^^^^^^^^^^^^^^^^^^^^^^^^^
  File "/home/airflow/.local/lib/python3.12/site-packages/airflow/hooks/base.py", line 83, in get_connection
    conn = Connection.get_connection_from_secrets(conn_id)
           ^^^^^^^^^^^^^^^^^^^^^^^^^^^^^^^^^^^^^^^^^^^^^^^
  File "/home/airflow/.local/lib/python3.12/site-packages/airflow/models/connection.py", line 537, in get_connection_from_secrets
    raise AirflowNotFoundException(f"The conn_id `{conn_id}` isn't defined")
airflow.exceptions.AirflowNotFoundException: The conn_id `snowflake_conn` isn't defined
[2025-04-20T21:59:04.630+0000] {processor.py:927} WARNING - No viable dags retrieved from /opt/airflow/dags/build_elt_with_dbt.py
[2025-04-20T21:59:04.646+0000] {processor.py:208} INFO - Processing /opt/airflow/dags/build_elt_with_dbt.py took 0.074 seconds
[2025-04-20T21:59:35.072+0000] {processor.py:186} INFO - Started process (PID=872) to work on /opt/airflow/dags/build_elt_with_dbt.py
[2025-04-20T21:59:35.073+0000] {processor.py:914} INFO - Processing file /opt/airflow/dags/build_elt_with_dbt.py for tasks to queue
[2025-04-20T21:59:35.076+0000] {logging_mixin.py:190} INFO - [2025-04-20T21:59:35.076+0000] {dagbag.py:587} INFO - Filling up the DagBag from /opt/airflow/dags/build_elt_with_dbt.py
[2025-04-20T21:59:35.118+0000] {logging_mixin.py:190} INFO - [2025-04-20T21:59:35.114+0000] {dagbag.py:386} ERROR - Failed to import: /opt/airflow/dags/build_elt_with_dbt.py
Traceback (most recent call last):
  File "/home/airflow/.local/lib/python3.12/site-packages/airflow/models/dagbag.py", line 382, in parse
    loader.exec_module(new_module)
  File "<frozen importlib._bootstrap_external>", line 995, in exec_module
  File "<frozen importlib._bootstrap>", line 488, in _call_with_frames_removed
  File "/opt/airflow/dags/build_elt_with_dbt.py", line 16, in <module>
    conn = BaseHook.get_connection('snowflake_conn')
           ^^^^^^^^^^^^^^^^^^^^^^^^^^^^^^^^^^^^^^^^^
  File "/home/airflow/.local/lib/python3.12/site-packages/airflow/hooks/base.py", line 83, in get_connection
    conn = Connection.get_connection_from_secrets(conn_id)
           ^^^^^^^^^^^^^^^^^^^^^^^^^^^^^^^^^^^^^^^^^^^^^^^
  File "/home/airflow/.local/lib/python3.12/site-packages/airflow/models/connection.py", line 537, in get_connection_from_secrets
    raise AirflowNotFoundException(f"The conn_id `{conn_id}` isn't defined")
airflow.exceptions.AirflowNotFoundException: The conn_id `snowflake_conn` isn't defined
[2025-04-20T21:59:35.119+0000] {processor.py:927} WARNING - No viable dags retrieved from /opt/airflow/dags/build_elt_with_dbt.py
[2025-04-20T21:59:35.129+0000] {processor.py:208} INFO - Processing /opt/airflow/dags/build_elt_with_dbt.py took 0.071 seconds
[2025-04-20T22:00:05.513+0000] {processor.py:186} INFO - Started process (PID=888) to work on /opt/airflow/dags/build_elt_with_dbt.py
[2025-04-20T22:00:05.515+0000] {processor.py:914} INFO - Processing file /opt/airflow/dags/build_elt_with_dbt.py for tasks to queue
[2025-04-20T22:00:05.519+0000] {logging_mixin.py:190} INFO - [2025-04-20T22:00:05.519+0000] {dagbag.py:587} INFO - Filling up the DagBag from /opt/airflow/dags/build_elt_with_dbt.py
[2025-04-20T22:00:05.572+0000] {logging_mixin.py:190} INFO - [2025-04-20T22:00:05.564+0000] {dagbag.py:386} ERROR - Failed to import: /opt/airflow/dags/build_elt_with_dbt.py
Traceback (most recent call last):
  File "/home/airflow/.local/lib/python3.12/site-packages/airflow/models/dagbag.py", line 382, in parse
    loader.exec_module(new_module)
  File "<frozen importlib._bootstrap_external>", line 995, in exec_module
  File "<frozen importlib._bootstrap>", line 488, in _call_with_frames_removed
  File "/opt/airflow/dags/build_elt_with_dbt.py", line 16, in <module>
    conn = BaseHook.get_connection('snowflake_conn')
           ^^^^^^^^^^^^^^^^^^^^^^^^^^^^^^^^^^^^^^^^^
  File "/home/airflow/.local/lib/python3.12/site-packages/airflow/hooks/base.py", line 83, in get_connection
    conn = Connection.get_connection_from_secrets(conn_id)
           ^^^^^^^^^^^^^^^^^^^^^^^^^^^^^^^^^^^^^^^^^^^^^^^
  File "/home/airflow/.local/lib/python3.12/site-packages/airflow/models/connection.py", line 537, in get_connection_from_secrets
    raise AirflowNotFoundException(f"The conn_id `{conn_id}` isn't defined")
airflow.exceptions.AirflowNotFoundException: The conn_id `snowflake_conn` isn't defined
[2025-04-20T22:00:05.573+0000] {processor.py:927} WARNING - No viable dags retrieved from /opt/airflow/dags/build_elt_with_dbt.py
[2025-04-20T22:00:05.585+0000] {processor.py:208} INFO - Processing /opt/airflow/dags/build_elt_with_dbt.py took 0.079 seconds
[2025-04-20T22:00:36.022+0000] {processor.py:186} INFO - Started process (PID=904) to work on /opt/airflow/dags/build_elt_with_dbt.py
[2025-04-20T22:00:36.024+0000] {processor.py:914} INFO - Processing file /opt/airflow/dags/build_elt_with_dbt.py for tasks to queue
[2025-04-20T22:00:36.027+0000] {logging_mixin.py:190} INFO - [2025-04-20T22:00:36.027+0000] {dagbag.py:587} INFO - Filling up the DagBag from /opt/airflow/dags/build_elt_with_dbt.py
[2025-04-20T22:00:36.059+0000] {logging_mixin.py:190} INFO - [2025-04-20T22:00:36.054+0000] {dagbag.py:386} ERROR - Failed to import: /opt/airflow/dags/build_elt_with_dbt.py
Traceback (most recent call last):
  File "/home/airflow/.local/lib/python3.12/site-packages/airflow/models/dagbag.py", line 382, in parse
    loader.exec_module(new_module)
  File "<frozen importlib._bootstrap_external>", line 995, in exec_module
  File "<frozen importlib._bootstrap>", line 488, in _call_with_frames_removed
  File "/opt/airflow/dags/build_elt_with_dbt.py", line 16, in <module>
    conn = BaseHook.get_connection('snowflake_conn')
           ^^^^^^^^^^^^^^^^^^^^^^^^^^^^^^^^^^^^^^^^^
  File "/home/airflow/.local/lib/python3.12/site-packages/airflow/hooks/base.py", line 83, in get_connection
    conn = Connection.get_connection_from_secrets(conn_id)
           ^^^^^^^^^^^^^^^^^^^^^^^^^^^^^^^^^^^^^^^^^^^^^^^
  File "/home/airflow/.local/lib/python3.12/site-packages/airflow/models/connection.py", line 537, in get_connection_from_secrets
    raise AirflowNotFoundException(f"The conn_id `{conn_id}` isn't defined")
airflow.exceptions.AirflowNotFoundException: The conn_id `snowflake_conn` isn't defined
[2025-04-20T22:00:36.060+0000] {processor.py:927} WARNING - No viable dags retrieved from /opt/airflow/dags/build_elt_with_dbt.py
[2025-04-20T22:00:36.072+0000] {processor.py:208} INFO - Processing /opt/airflow/dags/build_elt_with_dbt.py took 0.057 seconds
[2025-04-20T22:01:06.480+0000] {processor.py:186} INFO - Started process (PID=920) to work on /opt/airflow/dags/build_elt_with_dbt.py
[2025-04-20T22:01:06.482+0000] {processor.py:914} INFO - Processing file /opt/airflow/dags/build_elt_with_dbt.py for tasks to queue
[2025-04-20T22:01:06.485+0000] {logging_mixin.py:190} INFO - [2025-04-20T22:01:06.484+0000] {dagbag.py:587} INFO - Filling up the DagBag from /opt/airflow/dags/build_elt_with_dbt.py
[2025-04-20T22:01:06.519+0000] {logging_mixin.py:190} INFO - [2025-04-20T22:01:06.514+0000] {dagbag.py:386} ERROR - Failed to import: /opt/airflow/dags/build_elt_with_dbt.py
Traceback (most recent call last):
  File "/home/airflow/.local/lib/python3.12/site-packages/airflow/models/dagbag.py", line 382, in parse
    loader.exec_module(new_module)
  File "<frozen importlib._bootstrap_external>", line 995, in exec_module
  File "<frozen importlib._bootstrap>", line 488, in _call_with_frames_removed
  File "/opt/airflow/dags/build_elt_with_dbt.py", line 16, in <module>
    conn = BaseHook.get_connection('snowflake_conn')
           ^^^^^^^^^^^^^^^^^^^^^^^^^^^^^^^^^^^^^^^^^
  File "/home/airflow/.local/lib/python3.12/site-packages/airflow/hooks/base.py", line 83, in get_connection
    conn = Connection.get_connection_from_secrets(conn_id)
           ^^^^^^^^^^^^^^^^^^^^^^^^^^^^^^^^^^^^^^^^^^^^^^^
  File "/home/airflow/.local/lib/python3.12/site-packages/airflow/models/connection.py", line 537, in get_connection_from_secrets
    raise AirflowNotFoundException(f"The conn_id `{conn_id}` isn't defined")
airflow.exceptions.AirflowNotFoundException: The conn_id `snowflake_conn` isn't defined
[2025-04-20T22:01:06.520+0000] {processor.py:927} WARNING - No viable dags retrieved from /opt/airflow/dags/build_elt_with_dbt.py
[2025-04-20T22:01:06.532+0000] {processor.py:208} INFO - Processing /opt/airflow/dags/build_elt_with_dbt.py took 0.060 seconds
[2025-04-20T22:01:36.956+0000] {processor.py:186} INFO - Started process (PID=936) to work on /opt/airflow/dags/build_elt_with_dbt.py
[2025-04-20T22:01:36.957+0000] {processor.py:914} INFO - Processing file /opt/airflow/dags/build_elt_with_dbt.py for tasks to queue
[2025-04-20T22:01:36.959+0000] {logging_mixin.py:190} INFO - [2025-04-20T22:01:36.959+0000] {dagbag.py:587} INFO - Filling up the DagBag from /opt/airflow/dags/build_elt_with_dbt.py
[2025-04-20T22:01:36.988+0000] {logging_mixin.py:190} INFO - [2025-04-20T22:01:36.984+0000] {dagbag.py:386} ERROR - Failed to import: /opt/airflow/dags/build_elt_with_dbt.py
Traceback (most recent call last):
  File "/home/airflow/.local/lib/python3.12/site-packages/airflow/models/dagbag.py", line 382, in parse
    loader.exec_module(new_module)
  File "<frozen importlib._bootstrap_external>", line 995, in exec_module
  File "<frozen importlib._bootstrap>", line 488, in _call_with_frames_removed
  File "/opt/airflow/dags/build_elt_with_dbt.py", line 16, in <module>
    conn = BaseHook.get_connection('snowflake_conn')
           ^^^^^^^^^^^^^^^^^^^^^^^^^^^^^^^^^^^^^^^^^
  File "/home/airflow/.local/lib/python3.12/site-packages/airflow/hooks/base.py", line 83, in get_connection
    conn = Connection.get_connection_from_secrets(conn_id)
           ^^^^^^^^^^^^^^^^^^^^^^^^^^^^^^^^^^^^^^^^^^^^^^^
  File "/home/airflow/.local/lib/python3.12/site-packages/airflow/models/connection.py", line 537, in get_connection_from_secrets
    raise AirflowNotFoundException(f"The conn_id `{conn_id}` isn't defined")
airflow.exceptions.AirflowNotFoundException: The conn_id `snowflake_conn` isn't defined
[2025-04-20T22:01:36.989+0000] {processor.py:927} WARNING - No viable dags retrieved from /opt/airflow/dags/build_elt_with_dbt.py
[2025-04-20T22:01:37.000+0000] {processor.py:208} INFO - Processing /opt/airflow/dags/build_elt_with_dbt.py took 0.051 seconds
[2025-04-20T22:02:07.440+0000] {processor.py:186} INFO - Started process (PID=951) to work on /opt/airflow/dags/build_elt_with_dbt.py
[2025-04-20T22:02:07.442+0000] {processor.py:914} INFO - Processing file /opt/airflow/dags/build_elt_with_dbt.py for tasks to queue
[2025-04-20T22:02:07.446+0000] {logging_mixin.py:190} INFO - [2025-04-20T22:02:07.446+0000] {dagbag.py:587} INFO - Filling up the DagBag from /opt/airflow/dags/build_elt_with_dbt.py
[2025-04-20T22:02:07.502+0000] {logging_mixin.py:190} INFO - [2025-04-20T22:02:07.491+0000] {dagbag.py:386} ERROR - Failed to import: /opt/airflow/dags/build_elt_with_dbt.py
Traceback (most recent call last):
  File "/home/airflow/.local/lib/python3.12/site-packages/airflow/models/dagbag.py", line 382, in parse
    loader.exec_module(new_module)
  File "<frozen importlib._bootstrap_external>", line 995, in exec_module
  File "<frozen importlib._bootstrap>", line 488, in _call_with_frames_removed
  File "/opt/airflow/dags/build_elt_with_dbt.py", line 16, in <module>
    conn = BaseHook.get_connection('snowflake_conn')
           ^^^^^^^^^^^^^^^^^^^^^^^^^^^^^^^^^^^^^^^^^
  File "/home/airflow/.local/lib/python3.12/site-packages/airflow/hooks/base.py", line 83, in get_connection
    conn = Connection.get_connection_from_secrets(conn_id)
           ^^^^^^^^^^^^^^^^^^^^^^^^^^^^^^^^^^^^^^^^^^^^^^^
  File "/home/airflow/.local/lib/python3.12/site-packages/airflow/models/connection.py", line 537, in get_connection_from_secrets
    raise AirflowNotFoundException(f"The conn_id `{conn_id}` isn't defined")
airflow.exceptions.AirflowNotFoundException: The conn_id `snowflake_conn` isn't defined
[2025-04-20T22:02:07.504+0000] {processor.py:927} WARNING - No viable dags retrieved from /opt/airflow/dags/build_elt_with_dbt.py
[2025-04-20T22:02:07.529+0000] {processor.py:208} INFO - Processing /opt/airflow/dags/build_elt_with_dbt.py took 0.101 seconds
[2025-04-20T22:02:37.849+0000] {processor.py:186} INFO - Started process (PID=967) to work on /opt/airflow/dags/build_elt_with_dbt.py
[2025-04-20T22:02:37.850+0000] {processor.py:914} INFO - Processing file /opt/airflow/dags/build_elt_with_dbt.py for tasks to queue
[2025-04-20T22:02:37.853+0000] {logging_mixin.py:190} INFO - [2025-04-20T22:02:37.852+0000] {dagbag.py:587} INFO - Filling up the DagBag from /opt/airflow/dags/build_elt_with_dbt.py
[2025-04-20T22:02:37.886+0000] {logging_mixin.py:190} INFO - [2025-04-20T22:02:37.881+0000] {dagbag.py:386} ERROR - Failed to import: /opt/airflow/dags/build_elt_with_dbt.py
Traceback (most recent call last):
  File "/home/airflow/.local/lib/python3.12/site-packages/airflow/models/dagbag.py", line 382, in parse
    loader.exec_module(new_module)
  File "<frozen importlib._bootstrap_external>", line 995, in exec_module
  File "<frozen importlib._bootstrap>", line 488, in _call_with_frames_removed
  File "/opt/airflow/dags/build_elt_with_dbt.py", line 16, in <module>
    conn = BaseHook.get_connection('snowflake_conn')
           ^^^^^^^^^^^^^^^^^^^^^^^^^^^^^^^^^^^^^^^^^
  File "/home/airflow/.local/lib/python3.12/site-packages/airflow/hooks/base.py", line 83, in get_connection
    conn = Connection.get_connection_from_secrets(conn_id)
           ^^^^^^^^^^^^^^^^^^^^^^^^^^^^^^^^^^^^^^^^^^^^^^^
  File "/home/airflow/.local/lib/python3.12/site-packages/airflow/models/connection.py", line 537, in get_connection_from_secrets
    raise AirflowNotFoundException(f"The conn_id `{conn_id}` isn't defined")
airflow.exceptions.AirflowNotFoundException: The conn_id `snowflake_conn` isn't defined
[2025-04-20T22:02:37.887+0000] {processor.py:927} WARNING - No viable dags retrieved from /opt/airflow/dags/build_elt_with_dbt.py
[2025-04-20T22:02:37.898+0000] {processor.py:208} INFO - Processing /opt/airflow/dags/build_elt_with_dbt.py took 0.054 seconds
[2025-04-20T22:03:08.340+0000] {processor.py:186} INFO - Started process (PID=983) to work on /opt/airflow/dags/build_elt_with_dbt.py
[2025-04-20T22:03:08.342+0000] {processor.py:914} INFO - Processing file /opt/airflow/dags/build_elt_with_dbt.py for tasks to queue
[2025-04-20T22:03:08.346+0000] {logging_mixin.py:190} INFO - [2025-04-20T22:03:08.346+0000] {dagbag.py:587} INFO - Filling up the DagBag from /opt/airflow/dags/build_elt_with_dbt.py
[2025-04-20T22:03:08.388+0000] {logging_mixin.py:190} INFO - [2025-04-20T22:03:08.382+0000] {dagbag.py:386} ERROR - Failed to import: /opt/airflow/dags/build_elt_with_dbt.py
Traceback (most recent call last):
  File "/home/airflow/.local/lib/python3.12/site-packages/airflow/models/dagbag.py", line 382, in parse
    loader.exec_module(new_module)
  File "<frozen importlib._bootstrap_external>", line 995, in exec_module
  File "<frozen importlib._bootstrap>", line 488, in _call_with_frames_removed
  File "/opt/airflow/dags/build_elt_with_dbt.py", line 16, in <module>
    conn = BaseHook.get_connection('snowflake_conn')
           ^^^^^^^^^^^^^^^^^^^^^^^^^^^^^^^^^^^^^^^^^
  File "/home/airflow/.local/lib/python3.12/site-packages/airflow/hooks/base.py", line 83, in get_connection
    conn = Connection.get_connection_from_secrets(conn_id)
           ^^^^^^^^^^^^^^^^^^^^^^^^^^^^^^^^^^^^^^^^^^^^^^^
  File "/home/airflow/.local/lib/python3.12/site-packages/airflow/models/connection.py", line 537, in get_connection_from_secrets
    raise AirflowNotFoundException(f"The conn_id `{conn_id}` isn't defined")
airflow.exceptions.AirflowNotFoundException: The conn_id `snowflake_conn` isn't defined
[2025-04-20T22:03:08.389+0000] {processor.py:927} WARNING - No viable dags retrieved from /opt/airflow/dags/build_elt_with_dbt.py
[2025-04-20T22:03:08.403+0000] {processor.py:208} INFO - Processing /opt/airflow/dags/build_elt_with_dbt.py took 0.077 seconds
[2025-04-20T22:03:38.741+0000] {processor.py:186} INFO - Started process (PID=999) to work on /opt/airflow/dags/build_elt_with_dbt.py
[2025-04-20T22:03:38.742+0000] {processor.py:914} INFO - Processing file /opt/airflow/dags/build_elt_with_dbt.py for tasks to queue
[2025-04-20T22:03:38.744+0000] {logging_mixin.py:190} INFO - [2025-04-20T22:03:38.744+0000] {dagbag.py:587} INFO - Filling up the DagBag from /opt/airflow/dags/build_elt_with_dbt.py
[2025-04-20T22:03:38.777+0000] {logging_mixin.py:190} INFO - [2025-04-20T22:03:38.773+0000] {dagbag.py:386} ERROR - Failed to import: /opt/airflow/dags/build_elt_with_dbt.py
Traceback (most recent call last):
  File "/home/airflow/.local/lib/python3.12/site-packages/airflow/models/dagbag.py", line 382, in parse
    loader.exec_module(new_module)
  File "<frozen importlib._bootstrap_external>", line 995, in exec_module
  File "<frozen importlib._bootstrap>", line 488, in _call_with_frames_removed
  File "/opt/airflow/dags/build_elt_with_dbt.py", line 16, in <module>
    conn = BaseHook.get_connection('snowflake_conn')
           ^^^^^^^^^^^^^^^^^^^^^^^^^^^^^^^^^^^^^^^^^
  File "/home/airflow/.local/lib/python3.12/site-packages/airflow/hooks/base.py", line 83, in get_connection
    conn = Connection.get_connection_from_secrets(conn_id)
           ^^^^^^^^^^^^^^^^^^^^^^^^^^^^^^^^^^^^^^^^^^^^^^^
  File "/home/airflow/.local/lib/python3.12/site-packages/airflow/models/connection.py", line 537, in get_connection_from_secrets
    raise AirflowNotFoundException(f"The conn_id `{conn_id}` isn't defined")
airflow.exceptions.AirflowNotFoundException: The conn_id `snowflake_conn` isn't defined
[2025-04-20T22:03:38.778+0000] {processor.py:927} WARNING - No viable dags retrieved from /opt/airflow/dags/build_elt_with_dbt.py
[2025-04-20T22:03:38.789+0000] {processor.py:208} INFO - Processing /opt/airflow/dags/build_elt_with_dbt.py took 0.054 seconds
[2025-04-20T22:04:09.236+0000] {processor.py:186} INFO - Started process (PID=1015) to work on /opt/airflow/dags/build_elt_with_dbt.py
[2025-04-20T22:04:09.237+0000] {processor.py:914} INFO - Processing file /opt/airflow/dags/build_elt_with_dbt.py for tasks to queue
[2025-04-20T22:04:09.241+0000] {logging_mixin.py:190} INFO - [2025-04-20T22:04:09.240+0000] {dagbag.py:587} INFO - Filling up the DagBag from /opt/airflow/dags/build_elt_with_dbt.py
[2025-04-20T22:04:09.284+0000] {logging_mixin.py:190} INFO - [2025-04-20T22:04:09.277+0000] {dagbag.py:386} ERROR - Failed to import: /opt/airflow/dags/build_elt_with_dbt.py
Traceback (most recent call last):
  File "/home/airflow/.local/lib/python3.12/site-packages/airflow/models/dagbag.py", line 382, in parse
    loader.exec_module(new_module)
  File "<frozen importlib._bootstrap_external>", line 995, in exec_module
  File "<frozen importlib._bootstrap>", line 488, in _call_with_frames_removed
  File "/opt/airflow/dags/build_elt_with_dbt.py", line 16, in <module>
    conn = BaseHook.get_connection('snowflake_conn')
           ^^^^^^^^^^^^^^^^^^^^^^^^^^^^^^^^^^^^^^^^^
  File "/home/airflow/.local/lib/python3.12/site-packages/airflow/hooks/base.py", line 83, in get_connection
    conn = Connection.get_connection_from_secrets(conn_id)
           ^^^^^^^^^^^^^^^^^^^^^^^^^^^^^^^^^^^^^^^^^^^^^^^
  File "/home/airflow/.local/lib/python3.12/site-packages/airflow/models/connection.py", line 537, in get_connection_from_secrets
    raise AirflowNotFoundException(f"The conn_id `{conn_id}` isn't defined")
airflow.exceptions.AirflowNotFoundException: The conn_id `snowflake_conn` isn't defined
[2025-04-20T22:04:09.285+0000] {processor.py:927} WARNING - No viable dags retrieved from /opt/airflow/dags/build_elt_with_dbt.py
[2025-04-20T22:04:09.298+0000] {processor.py:208} INFO - Processing /opt/airflow/dags/build_elt_with_dbt.py took 0.070 seconds
[2025-04-20T22:04:39.726+0000] {processor.py:186} INFO - Started process (PID=1031) to work on /opt/airflow/dags/build_elt_with_dbt.py
[2025-04-20T22:04:39.728+0000] {processor.py:914} INFO - Processing file /opt/airflow/dags/build_elt_with_dbt.py for tasks to queue
[2025-04-20T22:04:39.732+0000] {logging_mixin.py:190} INFO - [2025-04-20T22:04:39.732+0000] {dagbag.py:587} INFO - Filling up the DagBag from /opt/airflow/dags/build_elt_with_dbt.py
[2025-04-20T22:04:39.776+0000] {logging_mixin.py:190} INFO - [2025-04-20T22:04:39.769+0000] {dagbag.py:386} ERROR - Failed to import: /opt/airflow/dags/build_elt_with_dbt.py
Traceback (most recent call last):
  File "/home/airflow/.local/lib/python3.12/site-packages/airflow/models/dagbag.py", line 382, in parse
    loader.exec_module(new_module)
  File "<frozen importlib._bootstrap_external>", line 995, in exec_module
  File "<frozen importlib._bootstrap>", line 488, in _call_with_frames_removed
  File "/opt/airflow/dags/build_elt_with_dbt.py", line 16, in <module>
    conn = BaseHook.get_connection('snowflake_conn')
           ^^^^^^^^^^^^^^^^^^^^^^^^^^^^^^^^^^^^^^^^^
  File "/home/airflow/.local/lib/python3.12/site-packages/airflow/hooks/base.py", line 83, in get_connection
    conn = Connection.get_connection_from_secrets(conn_id)
           ^^^^^^^^^^^^^^^^^^^^^^^^^^^^^^^^^^^^^^^^^^^^^^^
  File "/home/airflow/.local/lib/python3.12/site-packages/airflow/models/connection.py", line 537, in get_connection_from_secrets
    raise AirflowNotFoundException(f"The conn_id `{conn_id}` isn't defined")
airflow.exceptions.AirflowNotFoundException: The conn_id `snowflake_conn` isn't defined
[2025-04-20T22:04:39.777+0000] {processor.py:927} WARNING - No viable dags retrieved from /opt/airflow/dags/build_elt_with_dbt.py
[2025-04-20T22:04:39.795+0000] {processor.py:208} INFO - Processing /opt/airflow/dags/build_elt_with_dbt.py took 0.081 seconds
[2025-04-20T22:05:10.246+0000] {processor.py:186} INFO - Started process (PID=1047) to work on /opt/airflow/dags/build_elt_with_dbt.py
[2025-04-20T22:05:10.248+0000] {processor.py:914} INFO - Processing file /opt/airflow/dags/build_elt_with_dbt.py for tasks to queue
[2025-04-20T22:05:10.252+0000] {logging_mixin.py:190} INFO - [2025-04-20T22:05:10.251+0000] {dagbag.py:587} INFO - Filling up the DagBag from /opt/airflow/dags/build_elt_with_dbt.py
[2025-04-20T22:05:10.308+0000] {logging_mixin.py:190} INFO - [2025-04-20T22:05:10.300+0000] {dagbag.py:386} ERROR - Failed to import: /opt/airflow/dags/build_elt_with_dbt.py
Traceback (most recent call last):
  File "/home/airflow/.local/lib/python3.12/site-packages/airflow/models/dagbag.py", line 382, in parse
    loader.exec_module(new_module)
  File "<frozen importlib._bootstrap_external>", line 995, in exec_module
  File "<frozen importlib._bootstrap>", line 488, in _call_with_frames_removed
  File "/opt/airflow/dags/build_elt_with_dbt.py", line 16, in <module>
    conn = BaseHook.get_connection('snowflake_conn')
           ^^^^^^^^^^^^^^^^^^^^^^^^^^^^^^^^^^^^^^^^^
  File "/home/airflow/.local/lib/python3.12/site-packages/airflow/hooks/base.py", line 83, in get_connection
    conn = Connection.get_connection_from_secrets(conn_id)
           ^^^^^^^^^^^^^^^^^^^^^^^^^^^^^^^^^^^^^^^^^^^^^^^
  File "/home/airflow/.local/lib/python3.12/site-packages/airflow/models/connection.py", line 537, in get_connection_from_secrets
    raise AirflowNotFoundException(f"The conn_id `{conn_id}` isn't defined")
airflow.exceptions.AirflowNotFoundException: The conn_id `snowflake_conn` isn't defined
[2025-04-20T22:05:10.309+0000] {processor.py:927} WARNING - No viable dags retrieved from /opt/airflow/dags/build_elt_with_dbt.py
[2025-04-20T22:05:10.321+0000] {processor.py:208} INFO - Processing /opt/airflow/dags/build_elt_with_dbt.py took 0.085 seconds
[2025-04-20T22:05:40.631+0000] {processor.py:186} INFO - Started process (PID=1069) to work on /opt/airflow/dags/build_elt_with_dbt.py
[2025-04-20T22:05:40.632+0000] {processor.py:914} INFO - Processing file /opt/airflow/dags/build_elt_with_dbt.py for tasks to queue
[2025-04-20T22:05:40.635+0000] {logging_mixin.py:190} INFO - [2025-04-20T22:05:40.634+0000] {dagbag.py:587} INFO - Filling up the DagBag from /opt/airflow/dags/build_elt_with_dbt.py
[2025-04-20T22:05:40.665+0000] {logging_mixin.py:190} INFO - [2025-04-20T22:05:40.659+0000] {dagbag.py:386} ERROR - Failed to import: /opt/airflow/dags/build_elt_with_dbt.py
Traceback (most recent call last):
  File "/home/airflow/.local/lib/python3.12/site-packages/airflow/models/dagbag.py", line 382, in parse
    loader.exec_module(new_module)
  File "<frozen importlib._bootstrap_external>", line 995, in exec_module
  File "<frozen importlib._bootstrap>", line 488, in _call_with_frames_removed
  File "/opt/airflow/dags/build_elt_with_dbt.py", line 16, in <module>
    conn = BaseHook.get_connection('snowflake_conn')
           ^^^^^^^^^^^^^^^^^^^^^^^^^^^^^^^^^^^^^^^^^
  File "/home/airflow/.local/lib/python3.12/site-packages/airflow/hooks/base.py", line 83, in get_connection
    conn = Connection.get_connection_from_secrets(conn_id)
           ^^^^^^^^^^^^^^^^^^^^^^^^^^^^^^^^^^^^^^^^^^^^^^^
  File "/home/airflow/.local/lib/python3.12/site-packages/airflow/models/connection.py", line 537, in get_connection_from_secrets
    raise AirflowNotFoundException(f"The conn_id `{conn_id}` isn't defined")
airflow.exceptions.AirflowNotFoundException: The conn_id `snowflake_conn` isn't defined
[2025-04-20T22:05:40.666+0000] {processor.py:927} WARNING - No viable dags retrieved from /opt/airflow/dags/build_elt_with_dbt.py
[2025-04-20T22:05:40.676+0000] {processor.py:208} INFO - Processing /opt/airflow/dags/build_elt_with_dbt.py took 0.052 seconds
