[2025-04-23T05:03:24.986+0000] {local_task_job_runner.py:123} INFO - ::group::Pre task execution logs
[2025-04-23T05:03:25.006+0000] {taskinstance.py:2612} INFO - Dependencies all met for dep_context=non-requeueable deps ti=<TaskInstance: BuildELT_dbt.dbt_run manual__2025-04-23T05:03:24.577517+00:00 [queued]>
[2025-04-23T05:03:25.017+0000] {taskinstance.py:2612} INFO - Dependencies all met for dep_context=requeueable deps ti=<TaskInstance: BuildELT_dbt.dbt_run manual__2025-04-23T05:03:24.577517+00:00 [queued]>
[2025-04-23T05:03:25.018+0000] {taskinstance.py:2865} INFO - Starting attempt 1 of 1
[2025-04-23T05:03:25.034+0000] {taskinstance.py:2888} INFO - Executing <Task(BashOperator): dbt_run> on 2025-04-23 05:03:24.577517+00:00
[2025-04-23T05:03:25.044+0000] {standard_task_runner.py:104} INFO - Running: ['***', 'tasks', 'run', 'BuildELT_dbt', 'dbt_run', 'manual__2025-04-23T05:03:24.577517+00:00', '--job-id', '61', '--raw', '--subdir', 'DAGS_FOLDER/build_elt_with_dbt.py', '--cfg-path', '/tmp/tmpvfk3crdg']
[2025-04-23T05:03:25.046+0000] {logging_mixin.py:190} WARNING - /home/***/.local/lib/python3.12/site-packages/***/task/task_runner/standard_task_runner.py:70 DeprecationWarning: This process (pid=953) is multi-threaded, use of fork() may lead to deadlocks in the child.
[2025-04-23T05:03:25.047+0000] {standard_task_runner.py:105} INFO - Job 61: Subtask dbt_run
[2025-04-23T05:03:25.047+0000] {standard_task_runner.py:72} INFO - Started process 954 to run task
[2025-04-23T05:03:25.094+0000] {task_command.py:467} INFO - Running <TaskInstance: BuildELT_dbt.dbt_run manual__2025-04-23T05:03:24.577517+00:00 [running]> on host 0b555a0ed01e
[2025-04-23T05:03:25.195+0000] {taskinstance.py:3131} INFO - Exporting env vars: AIRFLOW_CTX_DAG_OWNER='***' AIRFLOW_CTX_DAG_ID='BuildELT_dbt' AIRFLOW_CTX_TASK_ID='dbt_run' AIRFLOW_CTX_EXECUTION_DATE='2025-04-23T05:03:24.577517+00:00' AIRFLOW_CTX_TRY_NUMBER='1' AIRFLOW_CTX_DAG_RUN_ID='manual__2025-04-23T05:03:24.577517+00:00'
[2025-04-23T05:03:25.196+0000] {taskinstance.py:731} INFO - ::endgroup::
[2025-04-23T05:03:25.212+0000] {subprocess.py:63} INFO - Tmp dir root location: /tmp
[2025-04-23T05:03:25.214+0000] {subprocess.py:75} INFO - Running command: ['/usr/bin/bash', '-c', '/home/***/.local/bin/dbt run --profiles-dir /opt/***/dbt --project-dir /opt/***/dbt']
[2025-04-23T05:03:25.224+0000] {subprocess.py:86} INFO - Output:
[2025-04-23T05:03:28.393+0000] {subprocess.py:93} INFO - [0m05:03:28  Running with dbt=1.6.18
[2025-04-23T05:03:29.192+0000] {subprocess.py:93} INFO - [0m05:03:29  Registered adapter: snowflake=1.6.0
[2025-04-23T05:03:29.407+0000] {subprocess.py:93} INFO - [0m05:03:29  Found 2 tests, 2 models, 2 sources, 0 exposures, 0 metrics, 375 macros, 0 groups, 0 semantic models
[2025-04-23T05:03:29.410+0000] {subprocess.py:93} INFO - [0m05:03:29
[2025-04-23T05:03:32.121+0000] {subprocess.py:93} INFO - [0m05:03:32  Concurrency: 1 threads (target='dev')
[2025-04-23T05:03:32.125+0000] {subprocess.py:93} INFO - [0m05:03:32
[2025-04-23T05:03:32.149+0000] {subprocess.py:93} INFO - [0m05:03:32  1 of 2 START sql view model analytics.law_enforcement_calls .................... [RUN]
[2025-04-23T05:03:34.258+0000] {subprocess.py:93} INFO - [0m05:03:34  1 of 2 OK created sql view model analytics.law_enforcement_calls ............... [[32mSUCCESS 1[0m in 2.10s]
[2025-04-23T05:03:34.269+0000] {subprocess.py:93} INFO - [0m05:03:34  2 of 2 START sql view model analytics.Avg_response_time_pd ..................... [RUN]
[2025-04-23T05:03:35.283+0000] {subprocess.py:93} INFO - [0m05:03:35  2 of 2 ERROR creating sql view model analytics.Avg_response_time_pd ............ [[31mERROR[0m in 1.01s]
[2025-04-23T05:03:35.291+0000] {subprocess.py:93} INFO - [0m05:03:35
[2025-04-23T05:03:35.292+0000] {subprocess.py:93} INFO - [0m05:03:35  Finished running 2 view models in 0 hours 0 minutes and 5.88 seconds (5.88s).
[2025-04-23T05:03:35.325+0000] {subprocess.py:93} INFO - [0m05:03:35
[2025-04-23T05:03:35.326+0000] {subprocess.py:93} INFO - [0m05:03:35  [31mCompleted with 1 error and 0 warnings:[0m
[2025-04-23T05:03:35.327+0000] {subprocess.py:93} INFO - [0m05:03:35
[2025-04-23T05:03:35.327+0000] {subprocess.py:93} INFO - [0m05:03:35    Database Error in model Avg_response_time_pd (models/output/Avg_response_time_pd.sql)
[2025-04-23T05:03:35.328+0000] {subprocess.py:93} INFO -   001003 (42000): SQL compilation error:
[2025-04-23T05:03:35.328+0000] {subprocess.py:93} INFO -   syntax error line 16 at position 2 unexpected ')'.
[2025-04-23T05:03:35.328+0000] {subprocess.py:93} INFO -   compiled Code at target/run/lab2_dbt/models/output/Avg_response_time_pd.sql
[2025-04-23T05:03:35.329+0000] {subprocess.py:93} INFO - [0m05:03:35
[2025-04-23T05:03:35.329+0000] {subprocess.py:93} INFO - [0m05:03:35  Done. PASS=1 WARN=0 ERROR=1 SKIP=0 TOTAL=2
[2025-04-23T05:03:36.268+0000] {subprocess.py:97} INFO - Command exited with return code 1
[2025-04-23T05:03:36.277+0000] {taskinstance.py:3310} ERROR - Task failed with exception
Traceback (most recent call last):
  File "/home/airflow/.local/lib/python3.12/site-packages/airflow/models/taskinstance.py", line 767, in _execute_task
    result = _execute_callable(context=context, **execute_callable_kwargs)
             ^^^^^^^^^^^^^^^^^^^^^^^^^^^^^^^^^^^^^^^^^^^^^^^^^^^^^^^^^^^^^
  File "/home/airflow/.local/lib/python3.12/site-packages/airflow/models/taskinstance.py", line 733, in _execute_callable
    return ExecutionCallableRunner(
           ^^^^^^^^^^^^^^^^^^^^^^^^
  File "/home/airflow/.local/lib/python3.12/site-packages/airflow/utils/operator_helpers.py", line 252, in run
    return self.func(*args, **kwargs)
           ^^^^^^^^^^^^^^^^^^^^^^^^^^
  File "/home/airflow/.local/lib/python3.12/site-packages/airflow/models/baseoperator.py", line 406, in wrapper
    return func(self, *args, **kwargs)
           ^^^^^^^^^^^^^^^^^^^^^^^^^^^
  File "/home/airflow/.local/lib/python3.12/site-packages/airflow/operators/bash.py", line 249, in execute
    raise AirflowException(
airflow.exceptions.AirflowException: Bash command failed. The command returned a non-zero exit code 1.
[2025-04-23T05:03:36.285+0000] {taskinstance.py:1225} INFO - Marking task as FAILED. dag_id=BuildELT_dbt, task_id=dbt_run, run_id=manual__2025-04-23T05:03:24.577517+00:00, execution_date=20250423T050324, start_date=20250423T050325, end_date=20250423T050336
[2025-04-23T05:03:36.298+0000] {taskinstance.py:340} INFO - ::group::Post task execution logs
[2025-04-23T05:03:36.299+0000] {standard_task_runner.py:124} ERROR - Failed to execute job 61 for task dbt_run (Bash command failed. The command returned a non-zero exit code 1.; 954)
Traceback (most recent call last):
  File "/home/airflow/.local/lib/python3.12/site-packages/airflow/task/task_runner/standard_task_runner.py", line 117, in _start_by_fork
    ret = args.func(args, dag=self.dag)
          ^^^^^^^^^^^^^^^^^^^^^^^^^^^^^
  File "/home/airflow/.local/lib/python3.12/site-packages/airflow/cli/cli_config.py", line 49, in command
    return func(*args, **kwargs)
           ^^^^^^^^^^^^^^^^^^^^^
  File "/home/airflow/.local/lib/python3.12/site-packages/airflow/utils/cli.py", line 115, in wrapper
    return f(*args, **kwargs)
           ^^^^^^^^^^^^^^^^^^
  File "/home/airflow/.local/lib/python3.12/site-packages/airflow/cli/commands/task_command.py", line 483, in task_run
    task_return_code = _run_task_by_selected_method(args, _dag, ti)
                       ^^^^^^^^^^^^^^^^^^^^^^^^^^^^^^^^^^^^^^^^^^^^
  File "/home/airflow/.local/lib/python3.12/site-packages/airflow/cli/commands/task_command.py", line 256, in _run_task_by_selected_method
    return _run_raw_task(args, ti)
           ^^^^^^^^^^^^^^^^^^^^^^^
  File "/home/airflow/.local/lib/python3.12/site-packages/airflow/cli/commands/task_command.py", line 341, in _run_raw_task
    return ti._run_raw_task(
           ^^^^^^^^^^^^^^^^^
  File "/home/airflow/.local/lib/python3.12/site-packages/airflow/utils/session.py", line 97, in wrapper
    return func(*args, session=session, **kwargs)
           ^^^^^^^^^^^^^^^^^^^^^^^^^^^^^^^^^^^^^^
  File "/home/airflow/.local/lib/python3.12/site-packages/airflow/models/taskinstance.py", line 3004, in _run_raw_task
    return _run_raw_task(
           ^^^^^^^^^^^^^^
  File "/home/airflow/.local/lib/python3.12/site-packages/airflow/models/taskinstance.py", line 273, in _run_raw_task
    TaskInstance._execute_task_with_callbacks(
  File "/home/airflow/.local/lib/python3.12/site-packages/airflow/models/taskinstance.py", line 3158, in _execute_task_with_callbacks
    result = self._execute_task(context, task_orig)
             ^^^^^^^^^^^^^^^^^^^^^^^^^^^^^^^^^^^^^^
  File "/home/airflow/.local/lib/python3.12/site-packages/airflow/models/taskinstance.py", line 3182, in _execute_task
    return _execute_task(self, context, task_orig)
           ^^^^^^^^^^^^^^^^^^^^^^^^^^^^^^^^^^^^^^^
  File "/home/airflow/.local/lib/python3.12/site-packages/airflow/models/taskinstance.py", line 767, in _execute_task
    result = _execute_callable(context=context, **execute_callable_kwargs)
             ^^^^^^^^^^^^^^^^^^^^^^^^^^^^^^^^^^^^^^^^^^^^^^^^^^^^^^^^^^^^^
  File "/home/airflow/.local/lib/python3.12/site-packages/airflow/models/taskinstance.py", line 733, in _execute_callable
    return ExecutionCallableRunner(
           ^^^^^^^^^^^^^^^^^^^^^^^^
  File "/home/airflow/.local/lib/python3.12/site-packages/airflow/utils/operator_helpers.py", line 252, in run
    return self.func(*args, **kwargs)
           ^^^^^^^^^^^^^^^^^^^^^^^^^^
  File "/home/airflow/.local/lib/python3.12/site-packages/airflow/models/baseoperator.py", line 406, in wrapper
    return func(self, *args, **kwargs)
           ^^^^^^^^^^^^^^^^^^^^^^^^^^^
  File "/home/airflow/.local/lib/python3.12/site-packages/airflow/operators/bash.py", line 249, in execute
    raise AirflowException(
airflow.exceptions.AirflowException: Bash command failed. The command returned a non-zero exit code 1.
[2025-04-23T05:03:36.342+0000] {local_task_job_runner.py:266} INFO - Task exited with return code 1
[2025-04-23T05:03:36.385+0000] {taskinstance.py:3900} INFO - 0 downstream tasks scheduled from follow-on schedule check
[2025-04-23T05:03:36.394+0000] {local_task_job_runner.py:245} INFO - ::endgroup::
